<sdf version='1.6'>
  <model name='iCub'>
    <link name='base_link'>
      <pose frame=''>0 0 0 0 -0 0</pose>
      <inertial>
        <pose frame=''>0.024882 0.000104 -0.044081 0 -0 0</pose>
        <mass>5.09143</mass>
        <inertia>
          <ixx>0.0249124</ixx>
          <ixy>-1.55458e-05</ixy>
          <ixz>0.00170968</ixz>
          <iyy>0.0139679</iyy>
          <iyz>5.93488e-06</iyz>
          <izz>0.0202112</izz>
        </inertia>
      </inertial>
      <collision name='base_link_fixed_joint_lump__root_link_collision'>
        <pose frame=''>-0.0364 0 0.032 1.5708 -0 -1.5708</pose>
        <geometry>
          <mesh>
            <scale>0.001 0.001 0.001</scale>
            <uri>model://iCub/meshes/simmechanics/sim_sea_2-5_root_link_prt-binary.stl</uri>
          </mesh>
        </geometry>
      </collision>
      <visual name='base_link_fixed_joint_lump__root_link_visual'>
        <pose frame=''>-0.0364 0 0.032 1.5708 -0 -1.5708</pose>
        <geometry>
          <mesh>
            <scale>0.001 0.001 0.001</scale>
            <uri>model://iCub/meshes/simmechanics/sim_sea_2-5_root_link_prt-binary.stl</uri>
          </mesh>
        </geometry>
      </visual>
    </link>
    <link name='l_hip_1'>
      <pose frame=''>0.006452 -0.022386 -0.119913 1.5708 -0 -1.5708</pose>
      <inertial>
        <pose frame=''>0.041678 -6.3e-05 -0.000401 0 -0 0</pose>
        <mass>0.915608</mass>
        <inertia>
          <ixx>0.000402555</ixx>
          <ixy>1.07708e-06</ixy>
          <ixz>-1.569e-06</ixz>
          <iyy>0.000570806</iyy>
          <iyz>-6.5378e-07</iyz>
          <izz>0.00057937</izz>
        </inertia>
      </inertial>
      <collision name='l_hip_1_collision'>
        <pose frame=''>-0.022386 0.151913 0.042852 0 -0 0</pose>
        <geometry>
          <mesh>
            <scale>0.001 0.001 0.001</scale>
            <uri>model://iCub/meshes/simmechanics/sim_sea_2-5_l_hip_1_prt-binary.stl</uri>
          </mesh>
        </geometry>
      </collision>
      <visual name='l_hip_1_visual'>
        <pose frame=''>-0.022386 0.151913 0.042852 0 -0 0</pose>
        <geometry>
          <mesh>
            <scale>0.001 0.001 0.001</scale>
            <uri>model://iCub/meshes/simmechanics/sim_sea_2-5_l_hip_1_prt-binary.stl</uri>
          </mesh>
        </geometry>
      </visual>
    </link>
    <joint name='l_hip_pitch' type='revolute'>
      <child>l_hip_1</child>
      <parent>base_link</parent>
      <axis>
        <xyz>-0 1 0</xyz>
        <limit>
          <lower>-0.523599</lower>
          <upper>1.48353</upper>
          <effort>50000</effort>
          <velocity>50000</velocity>
        </limit>
        <dynamics>
          <damping>0.223</damping>
          <friction>0</friction>
          <spring_reference>0</spring_reference>
          <spring_stiffness>0</spring_stiffness>
        </dynamics>
        <use_parent_model_frame>1</use_parent_model_frame>
      </axis>
      <physics>
        <ode>
          <implicit_spring_damper>1</implicit_spring_damper>
          <cfm_damping>1</cfm_damping>
          <limit>
            <cfm>0</cfm>
            <erp>0.2</erp>
          </limit>
        </ode>
      </physics>
    </joint>
    <link name='l_hip_2'>
      <pose frame=''>0.031992 -0.0701 -0.119913 1.5708 -0 -1.5708</pose>
      <inertial>
        <pose frame=''>-1.9e-05 -0.044047 0.023959 0 -0 0</pose>
        <mass>0.421161</mass>
        <inertia>
          <ixx>0.000494475</ixx>
          <ixy>1.54783e-07</ixy>
          <ixz>-1.86267e-07</ixz>
          <iyy>0.000288821</iyy>
          <iyz>1.53903e-05</iyz>
          <izz>0.000319114</izz>
        </inertia>
      </inertial>
      <collision name='l_hip_2_collision'>
        <pose frame=''>-0.0701 0.151913 0.068392 0 -0 0</pose>
        <geometry>
          <mesh>
            <scale>0.001 0.001 0.001</scale>
            <uri>model://iCub/meshes/simmechanics/sim_sea_2-5_l_hip_2_prt-binary.stl</uri>
          </mesh>
        </geometry>
      </collision>
      <visual name='l_hip_2_visual'>
        <pose frame=''>-0.0701 0.151913 0.068392 0 -0 0</pose>
        <geometry>
          <mesh>
            <scale>0.001 0.001 0.001</scale>
            <uri>model://iCub/meshes/simmechanics/sim_sea_2-5_l_hip_2_prt-binary.stl</uri>
          </mesh>
        </geometry>
      </visual>
    </link>
    <joint name='l_hip_roll' type='revolute'>
      <child>l_hip_2</child>
      <parent>l_hip_1</parent>
      <axis>
        <xyz>-1 -0 0</xyz>
        <limit>
          <lower>0</lower>
          <upper>1.5708</upper>
          <effort>50000</effort>
          <velocity>50000</velocity>
        </limit>
        <dynamics>
          <damping>0.223</damping>
          <friction>0</friction>
          <spring_reference>0</spring_reference>
          <spring_stiffness>0</spring_stiffness>
        </dynamics>
        <use_parent_model_frame>1</use_parent_model_frame>
      </axis>
      <physics>
        <ode>
          <implicit_spring_damper>1</implicit_spring_damper>
          <cfm_damping>1</cfm_damping>
          <limit>
            <cfm>0</cfm>
            <erp>0.2</erp>
          </limit>
        </ode>
      </physics>
    </joint>
    <link name='l_hip_3'>
      <pose frame=''>0.007309 -0.0701 -0.194213 3.14159 -0 -3.14159</pose>
      <inertial>
        <pose frame=''>0.000282 -0.000123 0.008718 -1.5708 0 0</pose>
        <mass>0.126212</mass>
        <inertia>
          <ixx>0.01</ixx>
          <ixy>0</ixy>
          <ixz>0</ixz>
          <iyy>0.01</iyy>
          <iyz>0</iyz>
          <izz>0.01</izz>
        </inertia>
      </inertial>
      <collision name='l_hip_3_collision'>
        <pose frame=''>-0.0701 0.043709 -0.226213 -1.5708 0 0</pose>
        <geometry>
          <mesh>
            <scale>0.001 0.001 0.001</scale>
            <uri>model://iCub/meshes/simmechanics/sim_sea_2-5_l_upper_thigh_prt-binary.stl</uri>
          </mesh>
        </geometry>
      </collision>
      <visual name='l_hip_3_visual'>
        <pose frame=''>-0.0701 0.043709 -0.226213 -1.5708 0 0</pose>
        <geometry>
          <mesh>
            <scale>0.001 0.001 0.001</scale>
            <uri>model://iCub/meshes/simmechanics/sim_sea_2-5_l_upper_thigh_prt-binary.stl</uri>
          </mesh>
        </geometry>
      </visual>
    </link>
    <joint name='l_leg_ft_sensor' type='revolute'>
      <child>l_hip_3</child>
      <parent>l_hip_2</parent>
      <axis>
        <limit>
          <lower>0</lower>
          <upper>0</upper>
        </limit>
        <dynamics>
          <damping>0</damping>
          <friction>0</friction>
          <spring_reference>0</spring_reference>
          <spring_stiffness>0</spring_stiffness>
        </dynamics>
        <use_parent_model_frame>1</use_parent_model_frame>
        <xyz>0 0 1</xyz>
      </axis>
      <physics>
        <ode>
          <limit>
            <cfm>0</cfm>
            <erp>0.2</erp>
          </limit>
        </ode>
      </physics>
      <sensor name='l_leg_ft_sensor' type='force_torque'>
        <always_on>1</always_on>
        <update_rate>100</update_rate>
        <force_torque>
          <frame>child</frame>
          <measure_direction>child_to_parent</measure_direction>
        </force_torque>
      </sensor>
    </joint>
    <link name='l_upper_leg'>
      <pose frame=''>0.007309 -0.0701 -0.208813 1.5708 0 -1.5708</pose>
      <inertial>
        <pose frame=''>0.00015 -0.078827 0.003349 0 -0 0</pose>
        <mass>1.8084</mass>
        <inertia>
          <ixx>0.00647124</ixx>
          <ixy>-0.000117511</ixy>
          <ixz>-3.57295e-06</ixz>
          <iyy>0.00144844</iyy>
          <iyz>-0.000137709</iyz>
          <izz>0.00646464</izz>
        </inertia>
      </inertial>
      <collision name='l_upper_leg_collision'>
        <pose frame=''>-0.0701 0.241013 0.043709 0 -0 0</pose>
        <geometry>
          <mesh>
            <scale>0.001 0.001 0.001</scale>
            <uri>model://iCub/meshes/simmechanics/sim_sea_2-5_l_thigh_prt-binary.stl</uri>
          </mesh>
        </geometry>
      </collision>
      <visual name='l_upper_leg_visual'>
        <pose frame=''>-0.0701 0.241013 0.043709 0 -0 0</pose>
        <geometry>
          <mesh>
            <scale>0.001 0.001 0.001</scale>
            <uri>model://iCub/meshes/simmechanics/sim_sea_2-5_l_thigh_prt-binary.stl</uri>
          </mesh>
        </geometry>
      </visual>
    </link>
    <joint name='l_hip_yaw' type='revolute'>
      <child>l_upper_leg</child>
      <parent>l_hip_3</parent>
      <axis>
        <xyz>0 -0 1</xyz>
        <limit>
          <lower>-1.22173</lower>
          <upper>1.22173</upper>
          <effort>50000</effort>
          <velocity>50000</velocity>
        </limit>
        <dynamics>
          <damping>0.223</damping>
          <friction>0</friction>
          <spring_reference>0</spring_reference>
          <spring_stiffness>0</spring_stiffness>
        </dynamics>
        <use_parent_model_frame>1</use_parent_model_frame>
      </axis>
      <physics>
        <ode>
          <implicit_spring_damper>1</implicit_spring_damper>
          <cfm_damping>1</cfm_damping>
          <limit>
            <cfm>0</cfm>
            <erp>0.2</erp>
          </limit>
        </ode>
      </physics>
    </joint>
    <link name='l_lower_leg'>
      <pose frame=''>0.007309 -0.056515 -0.354438 1.5708 0 -1.5708</pose>
      <inertial>
        <pose frame=''>0.017167 -0.088615 0.000868 0 -0 0</pose>
        <mass>1.4724</mass>
        <inertia>
          <ixx>0.00423935</ixx>
          <ixy>-0.000240091</ixy>
          <ixz>6.75755e-05</ixz>
          <iyy>0.00151341</iyy>
          <iyz>-0.000229787</iyz>
          <izz>0.0045742</izz>
        </inertia>
      </inertial>
      <collision name='l_lower_leg_collision'>
        <pose frame=''>-0.056515 0.386638 0.043709 0 -0 0</pose>
        <geometry>
          <mesh>
            <scale>0.001 0.001 0.001</scale>
            <uri>model://iCub/meshes/simmechanics/sim_sea_2-5_l_shank_prt-binary.stl</uri>
          </mesh>
        </geometry>
      </collision>
      <visual name='l_lower_leg_visual'>
        <pose frame=''>-0.056515 0.386638 0.043709 0 -0 0</pose>
        <geometry>
          <mesh>
            <scale>0.001 0.001 0.001</scale>
            <uri>model://iCub/meshes/simmechanics/sim_sea_2-5_l_shank_prt-binary.stl</uri>
          </mesh>
        </geometry>
      </visual>
    </link>
    <joint name='l_knee' type='revolute'>
      <child>l_lower_leg</child>
      <parent>l_upper_leg</parent>
      <axis>
        <xyz>-0 1 0</xyz>
        <limit>
          <lower>-1.74533</lower>
          <upper>0</upper>
          <effort>50000</effort>
          <velocity>50000</velocity>
        </limit>
        <dynamics>
          <damping>0.223</damping>
          <friction>0</friction>
          <spring_reference>0</spring_reference>
          <spring_stiffness>0</spring_stiffness>
        </dynamics>
        <use_parent_model_frame>1</use_parent_model_frame>
      </axis>
      <physics>
        <ode>
          <implicit_spring_damper>1</implicit_spring_damper>
          <cfm_damping>1</cfm_damping>
          <limit>
            <cfm>0</cfm>
            <erp>0.2</erp>
          </limit>
        </ode>
      </physics>
    </joint>
    <link name='l_ankle_1'>
      <pose frame=''>0.007309 -0.097118 -0.554938 1.5708 0 -1.5708</pose>
      <inertial>
        <pose frame=''>-0.026112 6.3e-05 0.015261 0 -0 0</pose>
        <mass>0.6798</mass>
        <inertia>
          <ixx>0.000405061</ixx>
          <ixy>-1.12515e-06</ixy>
          <ixz>3.06764e-05</ixz>
          <iyy>0.000448346</iyy>
          <iyz>2.88993e-06</iyz>
          <izz>0.000309416</izz>
        </inertia>
      </inertial>
      <collision name='l_ankle_1_collision'>
        <pose frame=''>-0.097118 0.587138 0.043409 0 -0 0</pose>
        <geometry>
          <mesh>
            <scale>0.001 0.001 0.001</scale>
            <uri>model://iCub/meshes/simmechanics/sim_sea_2-5_l_ankle_prt-binary.stl</uri>
          </mesh>
        </geometry>
      </collision>
      <visual name='l_ankle_1_visual'>
        <pose frame=''>-0.097118 0.587138 0.043409 0 -0 0</pose>
        <geometry>
          <mesh>
            <scale>0.001 0.001 0.001</scale>
            <uri>model://iCub/meshes/simmechanics/sim_sea_2-5_l_ankle_prt-binary.stl</uri>
          </mesh>
        </geometry>
      </visual>
    </link>
    <joint name='l_ankle_pitch' type='revolute'>
      <child>l_ankle_1</child>
      <parent>l_lower_leg</parent>
      <axis>
        <xyz>0 -1 -0</xyz>
        <limit>
          <lower>-0.349066</lower>
          <upper>0.523599</upper>
          <effort>50000</effort>
          <velocity>50000</velocity>
        </limit>
        <dynamics>
          <damping>0.223</damping>
          <friction>0</friction>
          <spring_reference>0</spring_reference>
          <spring_stiffness>0</spring_stiffness>
        </dynamics>
        <use_parent_model_frame>1</use_parent_model_frame>
      </axis>
      <physics>
        <ode>
          <implicit_spring_damper>1</implicit_spring_damper>
          <cfm_damping>1</cfm_damping>
          <limit>
            <cfm>0</cfm>
            <erp>0.2</erp>
          </limit>
        </ode>
      </physics>
    </joint>
    <link name='l_ankle_2'>
      <pose frame=''>-0.040779 -0.0701 -0.554938 1.5708 0 -1.5708</pose>
      <inertial>
        <pose frame=''>-8e-06 -0.038202 -0.04732 0 -0 0</pose>
        <mass>0.267485</mass>
        <inertia>
          <ixx>0.01</ixx>
          <ixy>0</ixy>
          <ixz>0</ixz>
          <iyy>0.01</iyy>
          <iyz>0</iyz>
          <izz>0.01</izz>
        </inertia>
      </inertial>
      <collision name='l_ankle_2_collision'>
        <pose frame=''>-0.0701 0.587138 -0.004679 0 -0 0</pose>
        <geometry>
          <mesh>
            <scale>0.001 0.001 0.001</scale>
            <uri>model://iCub/meshes/simmechanics/sim_sea_2-5_l_foot_prt-binary.stl</uri>
          </mesh>
        </geometry>
      </collision>
      <visual name='l_ankle_2_visual'>
        <pose frame=''>-0.0701 0.587138 -0.004679 0 -0 0</pose>
        <geometry>
          <mesh>
            <scale>0.001 0.001 0.001</scale>
            <uri>model://iCub/meshes/simmechanics/sim_sea_2-5_l_foot_prt-binary.stl</uri>
          </mesh>
        </geometry>
      </visual>
    </link>
    <joint name='l_ankle_roll' type='revolute'>
      <child>l_ankle_2</child>
      <parent>l_ankle_1</parent>
      <axis>
        <xyz>-1 -0 0</xyz>
        <limit>
          <lower>-0.349066</lower>
          <upper>0.349066</upper>
          <effort>50000</effort>
          <velocity>50000</velocity>
        </limit>
        <dynamics>
          <damping>0.223</damping>
          <friction>0</friction>
          <spring_reference>0</spring_reference>
          <spring_stiffness>0</spring_stiffness>
        </dynamics>
        <use_parent_model_frame>1</use_parent_model_frame>
      </axis>
      <physics>
        <ode>
          <implicit_spring_damper>1</implicit_spring_damper>
          <cfm_damping>1</cfm_damping>
          <limit>
            <cfm>0</cfm>
            <erp>0.2</erp>
          </limit>
        </ode>
      </physics>
    </joint>
    <link name='l_foot'>
      <pose frame=''>0.010809 -0.0701 -0.615238 3.14159 0 -3.14159</pose>
      <inertial>
        <pose frame=''>0.033691 -0.005366 -0.001154 -1.5708 -0 -1.5708</pose>
        <mass>0.382372</mass>
        <inertia>
          <ixx>0.00121061</ixx>
          <ixy>-3.65345e-07</ixy>
          <ixz>5.78649e-05</ixz>
          <iyy>0.00141515</iyy>
          <iyz>-7.67241e-06</iyz>
          <izz>0.000273665</izz>
        </inertia>
      </inertial>
      <collision name='l_foot_collision'>
        <pose frame=''>0.047209 0.0701 -0.647438 -1.5708 -0 -1.5708</pose>
        <geometry>
          <box>
            <size>0.15 0.07 0.03</size>
          </box>
        </geometry>
        <surface>
          <bounce>
            <restitution_coefficient>0</restitution_coefficient>
            <threshold>100000</threshold>
          </bounce>
          <contact>
            <ode>
              <kp>1.8e+07</kp>
              <kd>100</kd>
              <max_vel>100</max_vel>
              <min_depth>0.0001</min_depth>
            </ode>
          </contact>
          <friction>
            <ode>
              <mu>1</mu>
              <mu2>1</mu2>
              <fdir1>0 0 0</fdir1>
            </ode>
          </friction>
        </surface>
        <max_contacts>4</max_contacts>
      </collision>
      <visual name='l_foot_visual'>
        <pose frame=''>0.047209 0.0701 -0.647438 -1.5708 -0 -1.5708</pose>
        <geometry>
          <mesh>
            <scale>0.001 0.001 0.001</scale>
            <uri>model://iCub/meshes/simmechanics/sim_sea_2-5_l_sole_prt-binary.stl</uri>
          </mesh>
        </geometry>
        <material>
          <script>
            <uri>__default__</uri>
            <name>__default__</name>
          </script>
        </material>
      </visual>
      <velocity_decay/>
      <gravity>1</gravity>
      <velocity_decay/>
    </link>
    <joint name='l_foot_ft_sensor' type='revolute'>
      <child>l_foot</child>
      <parent>l_ankle_2</parent>
      <axis>
        <limit>
          <lower>0</lower>
          <upper>0</upper>
        </limit>
        <dynamics>
          <damping>0</damping>
          <friction>0</friction>
          <spring_reference>0</spring_reference>
          <spring_stiffness>0</spring_stiffness>
        </dynamics>
        <use_parent_model_frame>1</use_parent_model_frame>
        <xyz>0 0 1</xyz>
      </axis>
      <physics>
        <ode>
          <limit>
            <cfm>0</cfm>
            <erp>0.2</erp>
          </limit>
        </ode>
      </physics>
      <sensor name='l_foot_ft_sensor' type='force_torque'>
        <always_on>1</always_on>
        <update_rate>100</update_rate>
        <force_torque>
          <frame>child</frame>
          <measure_direction>child_to_parent</measure_direction>
        </force_torque>
      </sensor>
    </joint>
    <link name='r_hip_1'>
      <pose frame=''>0.006452 0.023366 -0.119913 1.5708 -0 -1.5708</pose>
      <inertial>
        <pose frame=''>-0.040711 -5.9e-05 -0.000523 0 -0 0</pose>
        <mass>0.920101</mass>
        <inertia>
          <ixx>0.000411114</ixx>
          <ixy>-3.6672e-06</ixy>
          <ixz>3.58037e-07</ixz>
          <iyy>0.000576521</iyy>
          <iyz>-2.19976e-06</iyz>
          <izz>0.000587325</izz>
        </inertia>
      </inertial>
      <collision name='r_hip_1_collision'>
        <pose frame=''>0.023366 0.151913 0.042852 0 -0 0</pose>
        <geometry>
          <mesh>
            <scale>0.001 0.001 0.001</scale>
            <uri>model://iCub/meshes/simmechanics/sim_sea_2-5_r_hip_1_prt-binary.stl</uri>
          </mesh>
        </geometry>
      </collision>
      <visual name='r_hip_1_visual'>
        <pose frame=''>0.023366 0.151913 0.042852 0 -0 0</pose>
        <geometry>
          <mesh>
            <scale>0.001 0.001 0.001</scale>
            <uri>model://iCub/meshes/simmechanics/sim_sea_2-5_r_hip_1_prt-binary.stl</uri>
          </mesh>
        </geometry>
      </visual>
    </link>
    <joint name='r_hip_pitch' type='revolute'>
      <child>r_hip_1</child>
      <parent>base_link</parent>
      <axis>
        <xyz>-0 1 0</xyz>
        <limit>
          <lower>-0.523599</lower>
          <upper>1.48353</upper>
          <effort>50000</effort>
          <velocity>50000</velocity>
        </limit>
        <dynamics>
          <damping>0.223</damping>
          <friction>0</friction>
          <spring_reference>0</spring_reference>
          <spring_stiffness>0</spring_stiffness>
        </dynamics>
        <use_parent_model_frame>1</use_parent_model_frame>
      </axis>
      <physics>
        <ode>
          <implicit_spring_damper>1</implicit_spring_damper>
          <cfm_damping>1</cfm_damping>
          <limit>
            <cfm>0</cfm>
            <erp>0.2</erp>
          </limit>
        </ode>
      </physics>
    </joint>
    <link name='r_hip_2'>
      <pose frame=''>0.032796 0.0701 -0.119913 1.5708 -0 -1.5708</pose>
      <inertial>
        <pose frame=''>4e-06 -0.044233 0.024898 0 -0 0</pose>
        <mass>0.4194</mass>
        <inertia>
          <ixx>0.00048916</ixx>
          <ixy>-2.70159e-07</ixy>
          <ixz>1.85233e-07</ixz>
          <iyy>0.00028697</iyy>
          <iyz>1.28773e-05</iyz>
          <izz>0.000315599</izz>
        </inertia>
      </inertial>
      <collision name='r_hip_2_collision'>
        <pose frame=''>0.0701 0.151913 0.069196 0 -0 0</pose>
        <geometry>
          <mesh>
            <scale>0.001 0.001 0.001</scale>
            <uri>model://iCub/meshes/simmechanics/sim_sea_2-5_r_hip_2_prt-binary.stl</uri>
          </mesh>
        </geometry>
      </collision>
      <visual name='r_hip_2_visual'>
        <pose frame=''>0.0701 0.151913 0.069196 0 -0 0</pose>
        <geometry>
          <mesh>
            <scale>0.001 0.001 0.001</scale>
            <uri>model://iCub/meshes/simmechanics/sim_sea_2-5_r_hip_2_prt-binary.stl</uri>
          </mesh>
        </geometry>
      </visual>
    </link>
    <joint name='r_hip_roll' type='revolute'>
      <child>r_hip_2</child>
      <parent>r_hip_1</parent>
      <axis>
        <xyz>1 0 -0</xyz>
        <limit>
          <lower>0</lower>
          <upper>1.5708</upper>
          <effort>50000</effort>
          <velocity>50000</velocity>
        </limit>
        <dynamics>
          <damping>0.223</damping>
          <friction>0</friction>
          <spring_reference>0</spring_reference>
          <spring_stiffness>0</spring_stiffness>
        </dynamics>
        <use_parent_model_frame>1</use_parent_model_frame>
      </axis>
      <physics>
        <ode>
          <implicit_spring_damper>1</implicit_spring_damper>
          <cfm_damping>1</cfm_damping>
          <limit>
            <cfm>0</cfm>
            <erp>0.2</erp>
          </limit>
        </ode>
      </physics>
    </joint>
    <link name='r_hip_3'>
      <pose frame=''>0.007309 0.0701 -0.194213 3.14159 -0 -3.14159</pose>
      <inertial>
        <pose frame=''>-0.000123 -0.000282 0.008718 -1.5708 -0 -1.5708</pose>
        <mass>0.126212</mass>
        <inertia>
          <ixx>0.01</ixx>
          <ixy>0</ixy>
          <ixz>0</ixz>
          <iyy>0.01</iyy>
          <iyz>0</iyz>
          <izz>0.01</izz>
        </inertia>
      </inertial>
      <collision name='r_hip_3_collision'>
        <pose frame=''>0.043709 -0.0701 -0.226213 -1.5708 -0 -1.5708</pose>
        <geometry>
          <mesh>
            <scale>0.001 0.001 0.001</scale>
            <uri>model://iCub/meshes/simmechanics/sim_sea_2-5_r_upper_thigh_prt-binary.stl</uri>
          </mesh>
        </geometry>
      </collision>
      <visual name='r_hip_3_visual'>
        <pose frame=''>0.043709 -0.0701 -0.226213 -1.5708 -0 -1.5708</pose>
        <geometry>
          <mesh>
            <scale>0.001 0.001 0.001</scale>
            <uri>model://iCub/meshes/simmechanics/sim_sea_2-5_r_upper_thigh_prt-binary.stl</uri>
          </mesh>
        </geometry>
      </visual>
    </link>
    <joint name='r_leg_ft_sensor' type='revolute'>
      <child>r_hip_3</child>
      <parent>r_hip_2</parent>
      <axis>
        <limit>
          <lower>0</lower>
          <upper>0</upper>
        </limit>
        <dynamics>
          <damping>0</damping>
          <friction>0</friction>
          <spring_reference>0</spring_reference>
          <spring_stiffness>0</spring_stiffness>
        </dynamics>
        <use_parent_model_frame>1</use_parent_model_frame>
        <xyz>0 0 1</xyz>
      </axis>
      <physics>
        <ode>
          <limit>
            <cfm>0</cfm>
            <erp>0.2</erp>
          </limit>
        </ode>
      </physics>
      <sensor name='r_leg_ft_sensor' type='force_torque'>
        <always_on>1</always_on>
        <update_rate>100</update_rate>
        <force_torque>
          <frame>child</frame>
          <measure_direction>child_to_parent</measure_direction>
        </force_torque>
      </sensor>
    </joint>
    <link name='r_upper_leg'>
      <pose frame=''>0.007309 0.0701 -0.208813 1.5708 0 -1.5708</pose>
      <inertial>
        <pose frame=''>-7.7e-05 -0.078866 0.003361 0 -0 0</pose>
        <mass>1.8035</mass>
        <inertia>
          <ixx>0.00646378</ixx>
          <ixy>0.000122686</ixy>
          <ixz>4.94532e-06</ixz>
          <iyy>0.0014454</iyy>
          <iyz>-0.000137533</iyz>
          <izz>0.00645583</izz>
        </inertia>
      </inertial>
      <collision name='r_upper_leg_collision'>
        <pose frame=''>0.0701 0.241013 0.043709 0 -0 0</pose>
        <geometry>
          <mesh>
            <scale>0.001 0.001 0.001</scale>
            <uri>model://iCub/meshes/simmechanics/sim_sea_2-5_r_thigh_prt-binary.stl</uri>
          </mesh>
        </geometry>
      </collision>
      <visual name='r_upper_leg_visual'>
        <pose frame=''>0.0701 0.241013 0.043709 0 -0 0</pose>
        <geometry>
          <mesh>
            <scale>0.001 0.001 0.001</scale>
            <uri>model://iCub/meshes/simmechanics/sim_sea_2-5_r_thigh_prt-binary.stl</uri>
          </mesh>
        </geometry>
      </visual>
    </link>
    <joint name='r_hip_yaw' type='revolute'>
      <child>r_upper_leg</child>
      <parent>r_hip_3</parent>
      <axis>
        <xyz>0 0 -1</xyz>
        <limit>
          <lower>-1.22173</lower>
          <upper>1.22173</upper>
          <effort>50000</effort>
          <velocity>50000</velocity>
        </limit>
        <dynamics>
          <damping>0.223</damping>
          <friction>0</friction>
          <spring_reference>0</spring_reference>
          <spring_stiffness>0</spring_stiffness>
        </dynamics>
        <use_parent_model_frame>1</use_parent_model_frame>
      </axis>
      <physics>
        <ode>
          <implicit_spring_damper>1</implicit_spring_damper>
          <cfm_damping>1</cfm_damping>
          <limit>
            <cfm>0</cfm>
            <erp>0.2</erp>
          </limit>
        </ode>
      </physics>
    </joint>
    <link name='r_lower_leg'>
      <pose frame=''>0.007309 0.079768 -0.354438 1.5708 0 -1.5708</pose>
      <inertial>
        <pose frame=''>0.006066 -0.088843 0.001105 0 -0 0</pose>
        <mass>1.472</mass>
        <inertia>
          <ixx>0.00424221</ixx>
          <ixy>0.000229532</ixy>
          <ixz>-5.53606e-05</ixz>
          <iyy>0.00151221</iyy>
          <iyz>-0.000260874</iyz>
          <izz>0.00457765</izz>
        </inertia>
      </inertial>
      <collision name='r_lower_leg_collision'>
        <pose frame=''>0.079768 0.386638 0.043709 0 -0 0</pose>
        <geometry>
          <mesh>
            <scale>0.001 0.001 0.001</scale>
            <uri>model://iCub/meshes/simmechanics/sim_sea_2-5_r_shank_prt-binary.stl</uri>
          </mesh>
        </geometry>
      </collision>
      <visual name='r_lower_leg_visual'>
        <pose frame=''>0.079768 0.386638 0.043709 0 -0 0</pose>
        <geometry>
          <mesh>
            <scale>0.001 0.001 0.001</scale>
            <uri>model://iCub/meshes/simmechanics/sim_sea_2-5_r_shank_prt-binary.stl</uri>
          </mesh>
        </geometry>
      </visual>
    </link>
    <joint name='r_knee' type='revolute'>
      <child>r_lower_leg</child>
      <parent>r_upper_leg</parent>
      <axis>
        <xyz>-0 1 0</xyz>
        <limit>
          <lower>-1.74533</lower>
          <upper>0</upper>
          <effort>50000</effort>
          <velocity>50000</velocity>
        </limit>
        <dynamics>
          <damping>0.223</damping>
          <friction>0</friction>
          <spring_reference>0</spring_reference>
          <spring_stiffness>0</spring_stiffness>
        </dynamics>
        <use_parent_model_frame>1</use_parent_model_frame>
      </axis>
      <physics>
        <ode>
          <implicit_spring_damper>1</implicit_spring_damper>
          <cfm_damping>1</cfm_damping>
          <limit>
            <cfm>0</cfm>
            <erp>0.2</erp>
          </limit>
        </ode>
      </physics>
    </joint>
    <link name='r_ankle_1'>
      <pose frame=''>0.007309 0.0986 -0.554938 1.5708 0 -1.5708</pose>
      <inertial>
        <pose frame=''>0.027628 6.3e-05 0.015251 0 -0 0</pose>
        <mass>0.6803</mass>
        <inertia>
          <ixx>0.000405201</ixx>
          <ixy>7.40602e-07</ixy>
          <ixz>-3.03315e-05</ixz>
          <iyy>0.000449108</iyy>
          <iyz>2.88976e-06</iyz>
          <izz>0.000310063</izz>
        </inertia>
      </inertial>
      <collision name='r_ankle_1_collision'>
        <pose frame=''>0.0986 0.587138 0.043709 0 -0 0</pose>
        <geometry>
          <mesh>
            <scale>0.001 0.001 0.001</scale>
            <uri>model://iCub/meshes/simmechanics/sim_sea_2-5_r_ankle_prt-binary.stl</uri>
          </mesh>
        </geometry>
      </collision>
      <visual name='r_ankle_1_visual'>
        <pose frame=''>0.0986 0.587138 0.043709 0 -0 0</pose>
        <geometry>
          <mesh>
            <scale>0.001 0.001 0.001</scale>
            <uri>model://iCub/meshes/simmechanics/sim_sea_2-5_r_ankle_prt-binary.stl</uri>
          </mesh>
        </geometry>
      </visual>
    </link>
    <joint name='r_ankle_pitch' type='revolute'>
      <child>r_ankle_1</child>
      <parent>r_lower_leg</parent>
      <axis>
        <xyz>0 -1 -0</xyz>
        <limit>
          <lower>-0.349066</lower>
          <upper>0.523599</upper>
          <effort>50000</effort>
          <velocity>50000</velocity>
        </limit>
        <dynamics>
          <damping>0.223</damping>
          <friction>0</friction>
          <spring_reference>0</spring_reference>
          <spring_stiffness>0</spring_stiffness>
        </dynamics>
        <use_parent_model_frame>1</use_parent_model_frame>
      </axis>
      <physics>
        <ode>
          <implicit_spring_damper>1</implicit_spring_damper>
          <cfm_damping>1</cfm_damping>
          <limit>
            <cfm>0</cfm>
            <erp>0.2</erp>
          </limit>
        </ode>
      </physics>
    </joint>
    <link name='r_ankle_2'>
      <pose frame=''>0.025809 0.0701 -0.554938 1.5708 0 -1.5708</pose>
      <inertial>
        <pose frame=''>-8e-06 -0.038202 0.019267 0 -0 0</pose>
        <mass>0.267485</mass>
        <inertia>
          <ixx>0.01</ixx>
          <ixy>0</ixy>
          <ixz>0</ixz>
          <iyy>0.01</iyy>
          <iyz>0</iyz>
          <izz>0.01</izz>
        </inertia>
      </inertial>
      <collision name='r_ankle_2_collision'>
        <pose frame=''>0.0701 0.587138 0.062209 0 -0 0</pose>
        <geometry>
          <mesh>
            <scale>0.001 0.001 0.001</scale>
            <uri>model://iCub/meshes/simmechanics/sim_sea_2-5_r_foot_prt-binary.stl</uri>
          </mesh>
        </geometry>
      </collision>
      <visual name='r_ankle_2_visual'>
        <pose frame=''>0.0701 0.587138 0.062209 0 -0 0</pose>
        <geometry>
          <mesh>
            <scale>0.001 0.001 0.001</scale>
            <uri>model://iCub/meshes/simmechanics/sim_sea_2-5_r_foot_prt-binary.stl</uri>
          </mesh>
        </geometry>
      </visual>
    </link>
    <joint name='r_ankle_roll' type='revolute'>
      <child>r_ankle_2</child>
      <parent>r_ankle_1</parent>
      <axis>
        <xyz>1 0 0</xyz>
        <limit>
          <lower>-0.349066</lower>
          <upper>0.349066</upper>
          <effort>50000</effort>
          <velocity>50000</velocity>
        </limit>
        <dynamics>
          <damping>0.223</damping>
          <friction>0</friction>
          <spring_reference>0</spring_reference>
          <spring_stiffness>0</spring_stiffness>
        </dynamics>
        <use_parent_model_frame>1</use_parent_model_frame>
      </axis>
      <physics>
        <ode>
          <implicit_spring_damper>1</implicit_spring_damper>
          <cfm_damping>1</cfm_damping>
          <limit>
            <cfm>0</cfm>
            <erp>0.2</erp>
          </limit>
        </ode>
      </physics>
    </joint>
    <link name='r_foot'>
      <pose frame=''>0.010809 0.0701 -0.615238 3.14159 0 -3.14159</pose>
      <inertial>
        <pose frame=''>0.033624 0.005365 -0.001138 -1.5708 -0 -1.5708</pose>
        <mass>0.38227</mass>
        <inertia>
          <ixx>0.00120765</ixx>
          <ixy>3.70545e-07</ixy>
          <ixz>-5.78137e-05</ixz>
          <iyy>0.00141242</iyy>
          <iyz>-7.82502e-06</iyz>
          <izz>0.000273419</izz>
        </inertia>
      </inertial>
      <collision name='r_foot_collision'>
        <pose frame=''>0.047209 -0.0701 -0.647438 -1.5708 -0 -1.5708</pose>
        <geometry>
          <box>
            <size>0.15 0.07 0.03</size>
          </box>
        </geometry>
      </collision>
      <visual name='r_foot_visual'>
        <pose frame=''>0.047209 -0.0701 -0.647438 -1.5708 -0 -1.5708</pose>
        <geometry>
          <mesh>
            <scale>0.001 0.001 0.001</scale>
            <uri>model://iCub/meshes/simmechanics/sim_sea_2-5_r_sole_prt-binary.stl</uri>
          </mesh>
        </geometry>
      </visual>
    </link>
    <joint name='r_foot_ft_sensor' type='revolute'>
      <child>r_foot</child>
      <parent>r_ankle_2</parent>
      <axis>
        <limit>
          <lower>0</lower>
          <upper>0</upper>
        </limit>
        <dynamics>
          <damping>0</damping>
          <friction>0</friction>
          <spring_reference>0</spring_reference>
          <spring_stiffness>0</spring_stiffness>
        </dynamics>
        <use_parent_model_frame>1</use_parent_model_frame>
        <xyz>0 0 1</xyz>
      </axis>
      <physics>
        <ode>
          <limit>
            <cfm>0</cfm>
            <erp>0.2</erp>
          </limit>
        </ode>
      </physics>
      <sensor name='r_foot_ft_sensor' type='force_torque'>
        <always_on>1</always_on>
        <update_rate>100</update_rate>
        <force_torque>
          <frame>child</frame>
          <measure_direction>child_to_parent</measure_direction>
        </force_torque>
      </sensor>
    </joint>
    <link name='torso_1'>
      <pose frame=''>0 0.027046 0 1.5708 -0 -1.5708</pose>
      <inertial>
        <pose frame=''>0.027092 0.029148 -0.00044 0 -0 0</pose>
        <mass>0.67144</mass>
        <inertia>
          <ixx>0.00040911</ixx>
          <ixy>-1.04522e-06</ixy>
          <ixz>-1.02516e-06</ixz>
          <iyy>0.000384141</iyy>
          <iyz>6.50708e-06</iyz>
          <izz>0.000299445</izz>
        </inertia>
      </inertial>
      <collision name='torso_1_collision'>
        <pose frame=''>0.027046 0.032 0.0364 0 -0 0</pose>
        <geometry>
          <mesh>
            <scale>0.001 0.001 0.001</scale>
            <uri>model://iCub/meshes/simmechanics/sim_sea_2-5_lap_belt_1_prt-binary.stl</uri>
          </mesh>
        </geometry>
      </collision>
      <visual name='torso_1_visual'>
        <pose frame=''>0.027046 0.032 0.0364 0 -0 0</pose>
        <geometry>
          <mesh>
            <scale>0.001 0.001 0.001</scale>
            <uri>model://iCub/meshes/simmechanics/sim_sea_2-5_lap_belt_1_prt-binary.stl</uri>
          </mesh>
        </geometry>
      </visual>
    </link>
    <joint name='torso_pitch' type='revolute'>
      <child>torso_1</child>
      <parent>base_link</parent>
      <axis>
        <xyz>0 -1 -0</xyz>
        <limit>
          <lower>-0.349066</lower>
          <upper>1.22173</upper>
          <effort>50000</effort>
          <velocity>50000</velocity>
        </limit>
        <dynamics>
          <damping>0.06</damping>
          <friction>0</friction>
          <spring_reference>0</spring_reference>
          <spring_stiffness>0</spring_stiffness>
        </dynamics>
        <use_parent_model_frame>1</use_parent_model_frame>
      </axis>
      <physics>
        <ode>
          <implicit_spring_damper>1</implicit_spring_damper>
          <cfm_damping>1</cfm_damping>
          <limit>
            <cfm>0</cfm>
            <erp>0.2</erp>
          </limit>
        </ode>
      </physics>
    </joint>
    <link name='torso_2'>
      <pose frame=''>0.057345 0 0.032 1.5708 -0 -1.5708</pose>
      <inertial>
        <pose frame=''>-0.000114 0.036153 0.057096 0 -0 0</pose>
        <mass>0.425685</mass>
        <inertia>
          <ixx>0.000829234</ixx>
          <ixy>2.37006e-08</ixy>
          <ixz>9.25231e-08</ixz>
          <iyy>0.000436517</iyy>
          <iyz>-1.74814e-07</iyz>
          <izz>0.000604802</izz>
        </inertia>
      </inertial>
      <collision name='torso_2_collision'>
        <pose frame=''>0 0.1433 0.038653 0 -0 0</pose>
        <geometry>
          <mesh>
            <scale>0.001 0.001 0.001</scale>
            <uri>model://iCub/meshes/simmechanics/sim_sea_2-5_lap_belt_2_prt-binary.stl</uri>
          </mesh>
        </geometry>
      </collision>
      <visual name='torso_2_visual'>
        <pose frame=''>0 0.1433 0.038653 0 -0 0</pose>
        <geometry>
          <mesh>
            <scale>0.001 0.001 0.001</scale>
            <uri>model://iCub/meshes/simmechanics/sim_sea_2-5_lap_belt_2_prt-binary.stl</uri>
          </mesh>
        </geometry>
      </visual>
    </link>
    <joint name='torso_roll' type='revolute'>
      <child>torso_2</child>
      <parent>torso_1</parent>
      <axis>
        <xyz>1 0 -0</xyz>
        <limit>
          <lower>-0.523599</lower>
          <upper>0.523599</upper>
          <effort>50000</effort>
          <velocity>50000</velocity>
        </limit>
        <dynamics>
          <damping>0.06</damping>
          <friction>0</friction>
          <spring_reference>0</spring_reference>
          <spring_stiffness>0</spring_stiffness>
        </dynamics>
        <use_parent_model_frame>1</use_parent_model_frame>
      </axis>
      <physics>
        <ode>
          <implicit_spring_damper>1</implicit_spring_damper>
          <cfm_damping>1</cfm_damping>
          <limit>
            <cfm>0</cfm>
            <erp>0.2</erp>
          </limit>
        </ode>
      </physics>
    </joint>
    <link name='chest'>
      <pose frame=''>-0.005498 0 0.082 1.5708 -0 -1.5708</pose>
      <inertial>
        <pose frame=''>0.000189 0.073091 -0.047238 0 -0 0</pose>
        <mass>7.638</mass>
        <inertia>
          <ixx>0.0430325</ixx>
          <ixy>2.91075e-05</ixy>
          <ixz>0.000181985</ixz>
          <iyy>0.0440836</iyy>
          <iyz>-0.000429106</iyz>
          <izz>0.0260563</izz>
        </inertia>
      </inertial>
      <collision name='chest_collision'>
        <pose frame=''>0 0.0928 -0.024189 0 -0 0</pose>
        <geometry>
          <mesh>
            <scale>0.001 0.001 0.001</scale>
            <uri>model://iCub/meshes/simmechanics/sim_sea_2-5_chest_bb_prt-binary.stl</uri>
          </mesh>
        </geometry>
      </collision>
      <visual name='chest_visual'>
        <pose frame=''>0 0.0928 -0.024189 0 -0 0</pose>
        <geometry>
          <mesh>
            <scale>0.001 0.001 0.001</scale>
            <uri>model://iCub/meshes/simmechanics/sim_sea_2-5_chest_bb_prt-binary.stl</uri>
          </mesh>
        </geometry>
      </visual>
    </link>
    <joint name='torso_yaw' type='revolute'>
      <child>chest</child>
      <parent>torso_2</parent>
      <axis>
        <xyz>-0 0 -1</xyz>
        <limit>
          <lower>-0.872665</lower>
          <upper>0.872665</upper>
          <effort>50000</effort>
          <velocity>50000</velocity>
        </limit>
        <dynamics>
          <damping>0.06</damping>
          <friction>0</friction>
          <spring_reference>0</spring_reference>
          <spring_stiffness>0</spring_stiffness>
        </dynamics>
        <use_parent_model_frame>1</use_parent_model_frame>
      </axis>
      <physics>
        <ode>
          <implicit_spring_damper>1</implicit_spring_damper>
          <cfm_damping>1</cfm_damping>
          <limit>
            <cfm>0</cfm>
            <erp>0.2</erp>
          </limit>
        </ode>
      </physics>
    </joint>
    <link name='l_shoulder_1'>
      <pose frame=''>-0.013467 -0.120016 0.1748 1.5708 -0 -1.5708</pose>
      <inertial>
        <pose frame=''>-0.008985 -3.3e-05 -0.0089 0 -0 0</pose>
        <mass>0.114882</mass>
        <inertia>
          <ixx>0.01</ixx>
          <ixy>0</ixy>
          <ixz>0</ixz>
          <iyy>0.01</iyy>
          <iyz>0</iyz>
          <izz>0.01</izz>
        </inertia>
      </inertial>
      <collision name='l_shoulder_1_collision'>
        <pose frame=''>-0.120257 0 -0.032223 0 -0 0</pose>
        <geometry>
          <mesh>
            <scale>0.001 0.001 0.001</scale>
            <uri>model://iCub/meshes/simmechanics/sim_sea_2-5_l_shoulder_1_prt-binary.stl</uri>
          </mesh>
        </geometry>
      </collision>
      <visual name='l_shoulder_1_visual'>
        <pose frame=''>-0.120257 0 -0.032223 0 -0 0</pose>
        <geometry>
          <mesh>
            <scale>0.001 0.001 0.001</scale>
            <uri>model://iCub/meshes/simmechanics/sim_sea_2-5_l_shoulder_1_prt-binary.stl</uri>
          </mesh>
        </geometry>
      </visual>
    </link>
    <joint name='l_shoulder_pitch' type='revolute'>
      <child>l_shoulder_1</child>
      <parent>chest</parent>
      <axis>
        <xyz>-0.258819 -0.965926 0</xyz>
        <limit>
          <lower>-1.66679</lower>
          <upper>0.174533</upper>
          <effort>50000</effort>
          <velocity>50000</velocity>
        </limit>
        <dynamics>
          <damping>0.06</damping>
          <friction>0</friction>
          <spring_reference>0</spring_reference>
          <spring_stiffness>0</spring_stiffness>
        </dynamics>
        <use_parent_model_frame>1</use_parent_model_frame>
      </axis>
      <physics>
        <ode>
          <implicit_spring_damper>1</implicit_spring_damper>
          <cfm_damping>1</cfm_damping>
          <limit>
            <cfm>0</cfm>
            <erp>0.2</erp>
          </limit>
        </ode>
      </physics>
    </joint>
    <link name='l_shoulder_2'>
      <pose frame=''>-0.021987 -0.106345 0.1748 -3.14159 1.309 -0.261799</pose>
      <inertial>
        <pose frame=''>0.021475 0.000269 -0.019411 0 -0 0</pose>
        <mass>0.238162</mass>
        <inertia>
          <ixx>0.01</ixx>
          <ixy>0</ixy>
          <ixz>0</ixz>
          <iyy>0.01</iyy>
          <iyz>0</iyz>
          <izz>0.01</izz>
        </inertia>
      </inertial>
      <collision name='l_shoulder_2_collision'>
        <pose frame=''>-0.106587 0 -0.040743 0 -0 0</pose>
        <geometry>
          <mesh>
            <scale>0.001 0.001 0.001</scale>
            <uri>model://iCub/meshes/simmechanics/sim_sea_2-5_l_shoulder_2_prt-binary.stl</uri>
          </mesh>
        </geometry>
      </collision>
      <visual name='l_shoulder_2_visual'>
        <pose frame=''>-0.106587 0 -0.040743 0 -0 0</pose>
        <geometry>
          <mesh>
            <scale>0.001 0.001 0.001</scale>
            <uri>model://iCub/meshes/simmechanics/sim_sea_2-5_l_shoulder_2_prt-binary.stl</uri>
          </mesh>
        </geometry>
      </visual>
    </link>
    <joint name='l_shoulder_roll' type='revolute'>
      <child>l_shoulder_2</child>
      <parent>l_shoulder_1</parent>
      <axis>
        <xyz>-0.965926 0.258819 0</xyz>
        <limit>
          <lower>0</lower>
          <upper>2.80649</upper>
          <effort>50000</effort>
          <velocity>50000</velocity>
        </limit>
        <dynamics>
          <damping>0.06</damping>
          <friction>0</friction>
          <spring_reference>0</spring_reference>
          <spring_stiffness>0</spring_stiffness>
        </dynamics>
        <use_parent_model_frame>1</use_parent_model_frame>
      </axis>
      <physics>
        <ode>
          <implicit_spring_damper>1</implicit_spring_damper>
          <cfm_damping>1</cfm_damping>
          <limit>
            <cfm>0</cfm>
            <erp>0.2</erp>
          </limit>
        </ode>
      </physics>
    </joint>
    <link name='l_shoulder_3'>
      <pose frame=''>-0.01062 -0.109391 0.151746 -3.14159 1.309 0</pose>
      <inertial>
        <pose frame=''>0.026798 -1.6e-05 0.014696 0 -0 0</pose>
        <mass>0.35913</mass>
        <inertia>
          <ixx>0.01</ixx>
          <ixy>0</ixy>
          <ixz>0</ixz>
          <iyy>0.01</iyy>
          <iyz>0</iyz>
          <izz>0.01</izz>
        </inertia>
      </inertial>
      <collision name='l_shoulder_3_collision'>
        <pose frame=''>-0.131901 0 -0.035343 0 -0 0</pose>
        <geometry>
          <mesh>
            <scale>0.001 0.001 0.001</scale>
            <uri>model://iCub/meshes/simmechanics/sim_sea_2-5_l_upper_arm_prt-binary.stl</uri>
          </mesh>
        </geometry>
      </collision>
      <visual name='l_shoulder_3_visual'>
        <pose frame=''>-0.131901 0 -0.035343 0 -0 0</pose>
        <geometry>
          <mesh>
            <scale>0.001 0.001 0.001</scale>
            <uri>model://iCub/meshes/simmechanics/sim_sea_2-5_l_upper_arm_prt-binary.stl</uri>
          </mesh>
        </geometry>
      </visual>
    </link>
    <joint name='l_shoulder_yaw' type='revolute'>
      <child>l_shoulder_3</child>
      <parent>l_shoulder_2</parent>
      <axis>
        <xyz>-0 0 -1</xyz>
        <limit>
          <lower>-0.645772</lower>
          <upper>1.39626</upper>
          <effort>50000</effort>
          <velocity>50000</velocity>
        </limit>
        <dynamics>
          <damping>0.06</damping>
          <friction>0</friction>
          <spring_reference>0</spring_reference>
          <spring_stiffness>0</spring_stiffness>
        </dynamics>
        <use_parent_model_frame>1</use_parent_model_frame>
      </axis>
      <physics>
        <ode>
          <implicit_spring_damper>1</implicit_spring_damper>
          <cfm_damping>1</cfm_damping>
          <limit>
            <cfm>0</cfm>
            <erp>0.2</erp>
          </limit>
        </ode>
      </physics>
    </joint>
    <link name='l_upper_arm'>
      <pose frame=''>-0.02562 -0.109391 0.095 3.14159 -0 -3.14159</pose>
      <inertial>
        <pose frame=''>-0.006121 -0.000189 0.029368 0 -1.309 3.14159</pose>
        <mass>0.746799</mass>
        <inertia>
          <ixx>0.000509731</ixx>
          <ixy>-6.90767e-07</ixy>
          <ixz>1.20048e-05</ixz>
          <iyy>0.00067086</iyy>
          <iyz>3.11833e-06</iyz>
          <izz>0.000601202</izz>
        </inertia>
      </inertial>
      <collision name='l_upper_arm_collision'>
        <pose frame=''>-0.015 0 -0.1933 0 -1.309 3.14159</pose>
        <geometry>
          <mesh>
            <scale>0.001 0.001 0.001</scale>
            <uri>model://iCub/meshes/simmechanics/sim_sea_2-5_l_elbow_prt-binary.stl</uri>
          </mesh>
        </geometry>
      </collision>
      <visual name='l_upper_arm_visual'>
        <pose frame=''>-0.015 0 -0.1933 0 -1.309 3.14159</pose>
        <geometry>
          <mesh>
            <scale>0.001 0.001 0.001</scale>
            <uri>model://iCub/meshes/simmechanics/sim_sea_2-5_l_elbow_prt-binary.stl</uri>
          </mesh>
        </geometry>
      </visual>
    </link>
    <joint name='l_arm_ft_sensor' type='revolute'>
      <child>l_upper_arm</child>
      <parent>l_shoulder_3</parent>
      <axis>
        <limit>
          <lower>0</lower>
          <upper>0</upper>
        </limit>
        <dynamics>
          <damping>0</damping>
          <friction>0</friction>
          <spring_reference>0</spring_reference>
          <spring_stiffness>0</spring_stiffness>
        </dynamics>
        <use_parent_model_frame>1</use_parent_model_frame>
        <xyz>0 0 1</xyz>
      </axis>
      <physics>
        <ode>
          <limit>
            <cfm>0</cfm>
            <erp>0.2</erp>
          </limit>
          <implicit_spring_damper>1</implicit_spring_damper>
          <cfm_damping>1</cfm_damping>
        </ode>
      </physics>
      <sensor name='l_arm_ft_sensor' type='force_torque'>
        <always_on>1</always_on>
        <update_rate>100</update_rate>
        <force_torque>
          <frame>child</frame>
          <measure_direction>child_to_parent</measure_direction>
        </force_torque>
      </sensor>
    </joint>
    <link name='l_elbow_1'>
      <pose frame=''>-0.02562 -0.075391 0.01574 -3.14159 1.309 0</pose>
      <inertial>
        <pose frame=''>0.006739 0.030302 -0.004658 0 -0 0</pose>
        <mass>0.267903</mass>
        <inertia>
          <ixx>0.01</ixx>
          <ixy>0</ixy>
          <ixz>0</ixz>
          <iyy>0.01</iyy>
          <iyz>0</iyz>
          <izz>0.01</izz>
        </inertia>
      </inertial>
      <collision name='l_elbow_1_collision'>
        <pose frame=''>-0.25939 0.034 -0.085033 0 -0 0</pose>
        <geometry>
          <mesh>
            <scale>0.001 0.001 0.001</scale>
            <uri>model://iCub/meshes/simmechanics/sim_sea_2-5_l_elbow_prosup_prt-binary.stl</uri>
          </mesh>
        </geometry>
      </collision>
      <visual name='l_elbow_1_visual'>
        <pose frame=''>-0.25939 0.034 -0.085033 0 -0 0</pose>
        <geometry>
          <mesh>
            <scale>0.001 0.001 0.001</scale>
            <uri>model://iCub/meshes/simmechanics/sim_sea_2-5_l_elbow_prosup_prt-binary.stl</uri>
          </mesh>
        </geometry>
      </visual>
    </link>
    <joint name='l_elbow' type='revolute'>
      <child>l_elbow_1</child>
      <parent>l_upper_arm</parent>
      <axis>
        <xyz>-0 1 0</xyz>
        <limit>
          <lower>0.261799</lower>
          <upper>1.85005</upper>
          <effort>50000</effort>
          <velocity>50000</velocity>
        </limit>
        <dynamics>
          <damping>0.06</damping>
          <friction>0</friction>
          <spring_reference>0</spring_reference>
          <spring_stiffness>0</spring_stiffness>
        </dynamics>
        <use_parent_model_frame>1</use_parent_model_frame>
      </axis>
      <physics>
        <ode>
          <implicit_spring_damper>1</implicit_spring_damper>
          <cfm_damping>1</cfm_damping>
          <limit>
            <cfm>0</cfm>
            <erp>0.2</erp>
          </limit>
        </ode>
      </physics>
    </joint>
    <link name='l_forearm'>
      <pose frame=''>-0.01062 -0.109391 -0.02006 -3.14159 1.309 0</pose>
      <inertial>
        <pose frame=''>0.040451 -0.000686 0.005324 0 -0 0</pose>
        <mass>0.636185</mass>
        <inertia>
          <ixx>0.000371447</ixx>
          <ixy>4.34562e-06</ixy>
          <ixz>-0.000105871</ixz>
          <iyy>0.000674229</iyy>
          <iyz>4.05222e-06</iyz>
          <izz>0.000557115</izz>
        </inertia>
      </inertial>
      <collision name='l_forearm_collision'>
        <pose frame=''>-0.296887 0 -0.079551 0 -0 0</pose>
        <geometry>
          <mesh>
            <scale>0.001 0.001 0.001</scale>
            <uri>model://iCub/meshes/simmechanics/sim_sea_2-5_l_forearm_prt-binary.stl</uri>
          </mesh>
        </geometry>
      </collision>
      <visual name='l_forearm_visual'>
        <pose frame=''>-0.296887 0 -0.079551 0 -0 0</pose>
        <geometry>
          <mesh>
            <scale>0.001 0.001 0.001</scale>
            <uri>model://iCub/meshes/simmechanics/sim_sea_2-5_l_forearm_prt-binary.stl</uri>
          </mesh>
        </geometry>
      </visual>
    </link>
    <joint name='l_wrist_prosup' type='revolute'>
      <child>l_forearm</child>
      <parent>l_elbow_1</parent>
      <axis>
        <xyz>-0 0 -1</xyz>
        <limit>
          <lower>-1.0472</lower>
          <upper>1.0472</upper>
          <effort>50000</effort>
          <velocity>50000</velocity>
        </limit>
        <dynamics>
          <damping>0.06</damping>
          <friction>0</friction>
          <spring_reference>0</spring_reference>
          <spring_stiffness>0</spring_stiffness>
        </dynamics>
        <use_parent_model_frame>1</use_parent_model_frame>
      </axis>
      <physics>
        <ode>
          <implicit_spring_damper>1</implicit_spring_damper>
          <cfm_damping>1</cfm_damping>
          <limit>
            <cfm>0</cfm>
            <erp>0.2</erp>
          </limit>
        </ode>
      </physics>
    </joint>
    <link name='l_wrist_1'>
      <pose frame=''>-0.00847 -0.109398 -0.12656 -3.14159 1.309 0</pose>
      <inertial>
        <pose frame=''>-0.000981 -0.001178 0.004083 0 -0 0</pose>
        <mass>0.0362152</mass>
        <inertia>
          <ixx>0.01</ixx>
          <ixy>0</ixy>
          <ixz>0</ixz>
          <iyy>0.01</iyy>
          <iyz>0</iyz>
          <izz>0.01</izz>
        </inertia>
      </inertial>
      <collision name='l_wrist_1_collision'>
        <pose frame=''>-0.400315 -7e-06 -0.105038 0 -0 0</pose>
        <geometry>
          <mesh>
            <scale>0.001 0.001 0.001</scale>
            <uri>model://iCub/meshes/simmechanics/sim_sea_2-5_l_wrist_pitch_prt-binary.stl</uri>
          </mesh>
        </geometry>
      </collision>
      <visual name='l_wrist_1_visual'>
        <pose frame=''>-0.400315 -7e-06 -0.105038 0 -0 0</pose>
        <geometry>
          <mesh>
            <scale>0.001 0.001 0.001</scale>
            <uri>model://iCub/meshes/simmechanics/sim_sea_2-5_l_wrist_pitch_prt-binary.stl</uri>
          </mesh>
        </geometry>
      </visual>
    </link>
    <joint name='l_wrist_pitch' type='revolute'>
      <child>l_wrist_1</child>
      <parent>l_forearm</parent>
      <axis>
        <xyz>1 0 -0</xyz>
        <limit>
          <lower>-1.39626</lower>
          <upper>0.436332</upper>
          <effort>50000</effort>
          <velocity>50000</velocity>
        </limit>
        <dynamics>
          <damping>0.06</damping>
          <friction>0</friction>
          <spring_reference>0</spring_reference>
          <spring_stiffness>0</spring_stiffness>
        </dynamics>
        <use_parent_model_frame>1</use_parent_model_frame>
      </axis>
      <physics>
        <ode>
          <implicit_spring_damper>1</implicit_spring_damper>
          <cfm_damping>1</cfm_damping>
          <limit>
            <cfm>0</cfm>
            <erp>0.2</erp>
          </limit>
        </ode>
      </physics>
    </joint>
    <link name='l_hand'>
      <pose frame=''>-0.01092 -0.089898 -0.12656 -3.14159 1.309 0</pose>
      <inertial>
        <pose frame=''>0.064768 0.00563 0.02266 0 -0 0</pose>
        <mass>0.247806</mass>
        <inertia>
          <ixx>0.01</ixx>
          <ixy>0</ixy>
          <ixz>0</ixz>
          <iyy>0.01</iyy>
          <iyz>0</iyz>
          <izz>0.01</izz>
        </inertia>
      </inertial>
      <collision name='l_hand_collision'>
        <pose frame=''>-0.39968 0.019493 -0.107405 0 -0 0</pose>
        <geometry>
          <mesh>
            <scale>0.001 0.001 0.001</scale>
            <uri>model://iCub/meshes/simmechanics/sim_sea_2-5_l_hand_prt-binary.stl</uri>
          </mesh>
        </geometry>
      </collision>
      <visual name='l_hand_visual'>
        <pose frame=''>-0.39968 0.019493 -0.107405 0 -0 0</pose>
        <geometry>
          <mesh>
            <scale>0.001 0.001 0.001</scale>
            <uri>model://iCub/meshes/simmechanics/sim_sea_2-5_l_hand_prt-binary.stl</uri>
          </mesh>
        </geometry>
      </visual>
    </link>
    <joint name='l_wrist_yaw' type='revolute'>
      <child>l_hand</child>
      <parent>l_wrist_1</parent>
      <axis>
        <xyz>0 -1 -0</xyz>
        <limit>
          <lower>-0.349066</lower>
          <upper>0.436332</upper>
          <effort>50000</effort>
          <velocity>50000</velocity>
        </limit>
        <dynamics>
          <damping>0.06</damping>
          <friction>0</friction>
          <spring_reference>0</spring_reference>
          <spring_stiffness>0</spring_stiffness>
        </dynamics>
        <use_parent_model_frame>1</use_parent_model_frame>
      </axis>
      <physics>
        <ode>
          <limit>
            <cfm>0</cfm>
            <erp>0.2</erp>
          </limit>
          <implicit_spring_damper>1</implicit_spring_damper>
          <cfm_damping>1</cfm_damping>
        </ode>
      </physics>
    </joint>
    <link name='neck_1'>
      <pose frame=''>-0.010809 0.0143 0.254797 1.5708 -0 -1.5708</pose>
      <inertial>
        <pose frame=''>0.014371 0.006567 -0.006384 0 -0 0</pose>
        <mass>0.125793</mass>
        <inertia>
          <ixx>0.01</ixx>
          <ixy>0</ixy>
          <ixz>0</ixz>
          <iyy>0.01</iyy>
          <iyz>0</iyz>
          <izz>0.01</izz>
        </inertia>
      </inertial>
      <collision name='neck_1_collision'>
        <pose frame=''>0.0143 -0.079997 -0.029501 0 -0 0</pose>
        <geometry>
          <mesh>
            <scale>0.001 0.001 0.001</scale>
            <uri>model://iCub/meshes/simmechanics/sim_sea_2-5_neck_1_prt-binary.stl</uri>
          </mesh>
        </geometry>
      </collision>
      <visual name='neck_1_visual'>
        <pose frame=''>0.0143 -0.079997 -0.029501 0 -0 0</pose>
        <geometry>
          <mesh>
            <scale>0.001 0.001 0.001</scale>
            <uri>model://iCub/meshes/simmechanics/sim_sea_2-5_neck_1_prt-binary.stl</uri>
          </mesh>
        </geometry>
      </visual>
    </link>
    <joint name='neck_pitch' type='revolute'>
      <child>neck_1</child>
      <parent>chest</parent>
      <axis>
        <xyz>-0 1 0</xyz>
        <limit>
          <lower>-0.698132</lower>
          <upper>0.383972</upper>
          <effort>50000</effort>
          <velocity>50000</velocity>
        </limit>
        <dynamics>
          <damping>0.06</damping>
          <friction>0</friction>
          <spring_reference>0</spring_reference>
          <spring_stiffness>0</spring_stiffness>
        </dynamics>
        <use_parent_model_frame>1</use_parent_model_frame>
      </axis>
    </joint>
    <link name='neck_2'>
      <pose frame=''>-0.031609 0 0.264297 1.5708 -0 -1.5708</pose>
      <inertial>
        <pose frame=''>-8.9e-05 0.035225 -0.019545 0 -0 0</pose>
        <mass>0.177087</mass>
        <inertia>
          <ixx>0.01</ixx>
          <ixy>0</ixy>
          <ixz>0</ixz>
          <iyy>0.01</iyy>
          <iyz>0</iyz>
          <izz>0.01</izz>
        </inertia>
      </inertial>
      <collision name='neck_2_collision'>
        <pose frame=''>0 -0.089497 -0.050301 0 -0 0</pose>
        <geometry>
          <mesh>
            <scale>0.001 0.001 0.001</scale>
            <uri>model://iCub/meshes/simmechanics/sim_sea_2-5_neck_2_prt-binary.stl</uri>
          </mesh>
        </geometry>
      </collision>
      <visual name='neck_2_visual'>
        <pose frame=''>0 -0.089497 -0.050301 0 -0 0</pose>
        <geometry>
          <mesh>
            <scale>0.001 0.001 0.001</scale>
            <uri>model://iCub/meshes/simmechanics/sim_sea_2-5_neck_2_prt-binary.stl</uri>
          </mesh>
        </geometry>
      </visual>
    </link>
    <joint name='neck_roll' type='revolute'>
      <child>neck_2</child>
      <parent>neck_1</parent>
      <axis>
        <xyz>-1 -0 0</xyz>
        <limit>
          <lower>-0.349066</lower>
          <upper>0.349066</upper>
          <effort>50000</effort>
          <velocity>50000</velocity>
        </limit>
        <dynamics>
          <damping>0.06</damping>
          <friction>0</friction>
          <spring_reference>0</spring_reference>
          <spring_stiffness>0</spring_stiffness>
        </dynamics>
        <use_parent_model_frame>1</use_parent_model_frame>
      </axis>
    </joint>
    <link name='head'>
      <pose frame=''>-0.010809 0 0.241953 1.5708 -0 -1.5708</pose>
      <inertial>
        <pose frame=''>-0.000574 0.113511 -0.007539 0 -0 0</pose>
        <mass>1.50691</mass>
        <inertia>
          <ixx>0.00680478</ixx>
          <ixy>-1.60267e-05</ixy>
          <ixz>7.28166e-05</ixz>
          <iyy>0.00634736</iyy>
          <iyz>0.000292091</iyz>
          <izz>0.00478116</izz>
        </inertia>
      </inertial>
      <collision name='head_collision'>
        <pose frame=''>0 -0.067153 -0.029501 0 -0 0</pose>
        <geometry>
          <mesh>
            <scale>0.001 0.001 0.001</scale>
            <uri>model://iCub/meshes/simmechanics/sim_sea_2-5_head_prt-binary.stl</uri>
          </mesh>
        </geometry>
        <surface>
          <contact>
            <ode/>
          </contact>
          <friction>
            <ode/>
          </friction>
        </surface>
      </collision>
      <visual name='head_visual'>
        <pose frame=''>0 -0.067153 -0.029501 0 -0 0</pose>
        <geometry>
          <mesh>
            <scale>0.001 0.001 0.001</scale>
            <uri>model://iCub/meshes/simmechanics/sim_sea_2-5_head_prt-binary.stl</uri>
          </mesh>
        </geometry>
        <material>
          <script>
            <uri>__default__</uri>
            <name>__default__</name>
          </script>
        </material>
      </visual>
      <gravity>1</gravity>
      <velocity_decay/>
      <sensor name='head_imu_acc_1x1' type='imu'>
        <always_on>1</always_on>
        <update_rate>100</update_rate>
        <pose frame=''>0.0095 0.133444 0.0093 -1.5708 1.5708 0</pose>
        <plugin name='iCub_yarp_gazebo_plugin_IMU' filename='libgazebo_yarp_imu.so'>
          <yarpConfigurationFile>model://iCub/conf/gazebo_icub_inertial.ini</yarpConfigurationFile>
        </plugin>
      </sensor>
    </link>
    <joint name='neck_yaw' type='revolute'>
      <child>head</child>
      <parent>neck_2</parent>
      <axis>
        <xyz>0 -0 1</xyz>
        <limit>
          <lower>-0.872665</lower>
          <upper>0.872665</upper>
          <effort>50000</effort>
          <velocity>50000</velocity>
        </limit>
        <dynamics>
          <damping>0.06</damping>
          <friction>0</friction>
          <spring_reference>0</spring_reference>
          <spring_stiffness>0</spring_stiffness>
        </dynamics>
        <use_parent_model_frame>1</use_parent_model_frame>
      </axis>
    </joint>
    <link name='r_shoulder_1'>
      <pose frame=''>-0.013467 0.120016 0.1748 -1.5708 -0 2.0944</pose>
      <inertial>
        <pose frame=''>-0.012266 3.2e-05 -0.003211 0 -0 0</pose>
        <mass>0.114862</mass>
        <inertia>
          <ixx>0.01</ixx>
          <ixy>0</ixy>
          <ixz>0</ixz>
          <iyy>0.01</iyy>
          <iyz>0</iyz>
          <izz>0.01</izz>
        </inertia>
      </inertial>
      <collision name='r_shoulder_1_collision'>
        <pose frame=''>0.099008 0 -0.026529 0 -0 0</pose>
        <geometry>
          <mesh>
            <scale>0.001 0.001 0.001</scale>
            <uri>model://iCub/meshes/simmechanics/sim_sea_2-5_r_shoulder_1_prt-binary.stl</uri>
          </mesh>
        </geometry>
      </collision>
      <visual name='r_shoulder_1_visual'>
        <pose frame=''>0.099008 0 -0.026529 0 -0 0</pose>
        <geometry>
          <mesh>
            <scale>0.001 0.001 0.001</scale>
            <uri>model://iCub/meshes/simmechanics/sim_sea_2-5_r_shoulder_1_prt-binary.stl</uri>
          </mesh>
        </geometry>
      </visual>
    </link>
    <joint name='r_shoulder_pitch' type='revolute'>
      <child>r_shoulder_1</child>
      <parent>chest</parent>
      <axis>
        <xyz>0.258819 -0.965926 -0</xyz>
        <limit>
          <lower>-1.66679</lower>
          <upper>0.174533</upper>
          <effort>50000</effort>
          <velocity>50000</velocity>
        </limit>
        <dynamics>
          <damping>0.06</damping>
          <friction>0</friction>
          <spring_reference>0</spring_reference>
          <spring_stiffness>0</spring_stiffness>
        </dynamics>
        <use_parent_model_frame>1</use_parent_model_frame>
      </axis>
      <physics>
        <ode>
          <implicit_spring_damper>1</implicit_spring_damper>
          <cfm_damping>1</cfm_damping>
          <limit>
            <cfm>0</cfm>
            <erp>0.2</erp>
          </limit>
        </ode>
      </physics>
    </joint>
    <link name='r_shoulder_2'>
      <pose frame=''>-0.021983 0.106346 0.1748 -3.14159 -1.309 -2.87979</pose>
      <inertial>
        <pose frame=''>-0.021414 0.000272 -0.01944 0 -0 0</pose>
        <mass>0.238162</mass>
        <inertia>
          <ixx>0.01</ixx>
          <ixy>0</ixy>
          <ixz>0</ixz>
          <iyy>0.01</iyy>
          <iyz>0</iyz>
          <izz>0.01</izz>
        </inertia>
      </inertial>
      <collision name='r_shoulder_2_collision'>
        <pose frame=''>0.106588 0 -0.040739 0 -0 0</pose>
        <geometry>
          <mesh>
            <scale>0.001 0.001 0.001</scale>
            <uri>model://iCub/meshes/simmechanics/sim_sea_2-5_r_shoulder_2_prt-binary.stl</uri>
          </mesh>
        </geometry>
      </collision>
      <visual name='r_shoulder_2_visual'>
        <pose frame=''>0.106588 0 -0.040739 0 -0 0</pose>
        <geometry>
          <mesh>
            <scale>0.001 0.001 0.001</scale>
            <uri>model://iCub/meshes/simmechanics/sim_sea_2-5_r_shoulder_2_prt-binary.stl</uri>
          </mesh>
        </geometry>
      </visual>
    </link>
    <joint name='r_shoulder_roll' type='revolute'>
      <child>r_shoulder_2</child>
      <parent>r_shoulder_1</parent>
      <axis>
        <xyz>0.965926 0.258819 -0</xyz>
        <limit>
          <lower>0</lower>
          <upper>2.80649</upper>
          <effort>50000</effort>
          <velocity>50000</velocity>
        </limit>
        <dynamics>
          <damping>0.06</damping>
          <friction>0</friction>
          <spring_reference>0</spring_reference>
          <spring_stiffness>0</spring_stiffness>
        </dynamics>
        <use_parent_model_frame>1</use_parent_model_frame>
      </axis>
      <physics>
        <ode>
          <implicit_spring_damper>1</implicit_spring_damper>
          <cfm_damping>1</cfm_damping>
          <limit>
            <cfm>0</cfm>
            <erp>0.2</erp>
          </limit>
        </ode>
      </physics>
    </joint>
    <link name='r_shoulder_3'>
      <pose frame=''>-0.01062 0.109391 0.151712 -3.14159 -1.309 -3.14159</pose>
      <inertial>
        <pose frame=''>-0.026762 -7e-06 0.0147 0 -0 0</pose>
        <mass>0.35913</mass>
        <inertia>
          <ixx>0.01</ixx>
          <ixy>0</ixy>
          <ixz>0</ixz>
          <iyy>0.01</iyy>
          <iyz>0</iyz>
          <izz>0.01</izz>
        </inertia>
      </inertial>
      <collision name='r_shoulder_3_collision'>
        <pose frame=''>0.131934 0 -0.035352 0 -0 0</pose>
        <geometry>
          <mesh>
            <scale>0.001 0.001 0.001</scale>
            <uri>model://iCub/meshes/simmechanics/sim_sea_2-5_r_upper_arm_prt-binary.stl</uri>
          </mesh>
        </geometry>
      </collision>
      <visual name='r_shoulder_3_visual'>
        <pose frame=''>0.131934 0 -0.035352 0 -0 0</pose>
        <geometry>
          <mesh>
            <scale>0.001 0.001 0.001</scale>
            <uri>model://iCub/meshes/simmechanics/sim_sea_2-5_r_upper_arm_prt-binary.stl</uri>
          </mesh>
        </geometry>
      </visual>
    </link>
    <joint name='r_shoulder_yaw' type='revolute'>
      <child>r_shoulder_3</child>
      <parent>r_shoulder_2</parent>
      <axis>
        <xyz>0 0 1</xyz>
        <limit>
          <lower>-0.645772</lower>
          <upper>1.39626</upper>
          <effort>50000</effort>
          <velocity>50000</velocity>
        </limit>
        <dynamics>
          <damping>0.06</damping>
          <friction>0</friction>
          <spring_reference>0</spring_reference>
          <spring_stiffness>0</spring_stiffness>
        </dynamics>
        <use_parent_model_frame>1</use_parent_model_frame>
      </axis>
      <physics>
        <ode>
          <implicit_spring_damper>1</implicit_spring_damper>
          <cfm_damping>1</cfm_damping>
          <limit>
            <cfm>0</cfm>
            <erp>0.2</erp>
          </limit>
        </ode>
      </physics>
    </joint>
    <link name='r_upper_arm'>
      <pose frame=''>-0.02562 0.109391 0.095 -3.14159 -0 -3.14159</pose>
      <inertial>
        <pose frame=''>-0.006087 0.000126 0.029312 0 1.309 0</pose>
        <mass>0.745104</mass>
        <inertia>
          <ixx>0.000509527</ixx>
          <ixy>1.19292e-06</ixy>
          <ixz>-1.17426e-05</ixz>
          <iyy>0.000668487</iyy>
          <iyz>1.13363e-06</iyz>
          <izz>0.000599254</izz>
        </inertia>
      </inertial>
      <collision name='r_upper_arm_collision'>
        <pose frame=''>-0.015 0 -0.1933 0 1.309 0</pose>
        <geometry>
          <mesh>
            <scale>0.001 0.001 0.001</scale>
            <uri>model://iCub/meshes/simmechanics/sim_sea_2-5_r_elbow_prt-binary.stl</uri>
          </mesh>
        </geometry>
      </collision>
      <visual name='r_upper_arm_visual'>
        <pose frame=''>-0.015 0 -0.1933 0 1.309 0</pose>
        <geometry>
          <mesh>
            <scale>0.001 0.001 0.001</scale>
            <uri>model://iCub/meshes/simmechanics/sim_sea_2-5_r_elbow_prt-binary.stl</uri>
          </mesh>
        </geometry>
      </visual>
    </link>
    <joint name='r_arm_ft_sensor' type='revolute'>
      <child>r_upper_arm</child>
      <parent>r_shoulder_3</parent>
      <axis>
        <limit>
          <lower>0</lower>
          <upper>0</upper>
        </limit>
        <dynamics>
          <damping>0</damping>
          <friction>0</friction>
          <spring_reference>0</spring_reference>
          <spring_stiffness>0</spring_stiffness>
        </dynamics>
        <use_parent_model_frame>1</use_parent_model_frame>
        <xyz>0 0 1</xyz>
      </axis>
      <physics>
        <ode>
          <limit>
            <cfm>0</cfm>
            <erp>0.2</erp>
          </limit>
          <implicit_spring_damper>1</implicit_spring_damper>
          <cfm_damping>1</cfm_damping>
        </ode>
      </physics>
      <sensor name='r_arm_ft_sensor' type='force_torque'>
        <always_on>1</always_on>
        <update_rate>100</update_rate>
        <force_torque>
          <frame>child</frame>
          <measure_direction>child_to_parent</measure_direction>
        </force_torque>
      </sensor>
    </joint>
    <link name='r_elbow_1'>
      <pose frame=''>-0.02562 0.086891 0.01574 -3.14159 -1.309 -3.14159</pose>
      <inertial>
        <pose frame=''>-0.006739 0.018802 -0.004658 0 -0 0</pose>
        <mass>0.267903</mass>
        <inertia>
          <ixx>0.01</ixx>
          <ixy>0</ixy>
          <ixz>0</ixz>
          <iyy>0.01</iyy>
          <iyz>0</iyz>
          <izz>0.01</izz>
        </inertia>
      </inertial>
      <collision name='r_elbow_1_collision'>
        <pose frame=''>0.25939 0.0225 -0.085033 0 -0 0</pose>
        <geometry>
          <mesh>
            <scale>0.001 0.001 0.001</scale>
            <uri>model://iCub/meshes/simmechanics/sim_sea_2-5_r_elbow_prosup_prt-binary.stl</uri>
          </mesh>
        </geometry>
      </collision>
      <visual name='r_elbow_1_visual'>
        <pose frame=''>0.25939 0.0225 -0.085033 0 -0 0</pose>
        <geometry>
          <mesh>
            <scale>0.001 0.001 0.001</scale>
            <uri>model://iCub/meshes/simmechanics/sim_sea_2-5_r_elbow_prosup_prt-binary.stl</uri>
          </mesh>
        </geometry>
      </visual>
    </link>
    <joint name='r_elbow' type='revolute'>
      <child>r_elbow_1</child>
      <parent>r_upper_arm</parent>
      <axis>
        <xyz>-0 1 -0</xyz>
        <limit>
          <lower>0.261799</lower>
          <upper>1.85005</upper>
          <effort>50000</effort>
          <velocity>50000</velocity>
        </limit>
        <dynamics>
          <damping>0.06</damping>
          <friction>0</friction>
          <spring_reference>0</spring_reference>
          <spring_stiffness>0</spring_stiffness>
        </dynamics>
        <use_parent_model_frame>1</use_parent_model_frame>
      </axis>
      <physics>
        <ode>
          <implicit_spring_damper>1</implicit_spring_damper>
          <cfm_damping>1</cfm_damping>
          <limit>
            <cfm>0</cfm>
            <erp>0.2</erp>
          </limit>
        </ode>
      </physics>
    </joint>
    <link name='r_forearm'>
      <pose frame=''>-0.01062 0.109391 -0.02006 -3.14159 -1.309 -3.14159</pose>
      <inertial>
        <pose frame=''>-0.040439 -0.000328 0.005327 0 -0 0</pose>
        <mass>0.6347</mass>
        <inertia>
          <ixx>0.000370044</ixx>
          <ixy>-1.65419e-06</ixy>
          <ixz>0.00010538</ixz>
          <iyy>0.000672279</iyy>
          <iyz>1.1456e-06</iyz>
          <izz>0.000553637</izz>
        </inertia>
      </inertial>
      <collision name='r_forearm_collision'>
        <pose frame=''>0.296887 0 -0.079551 0 -0 0</pose>
        <geometry>
          <mesh>
            <scale>0.001 0.001 0.001</scale>
            <uri>model://iCub/meshes/simmechanics/sim_sea_2-5_r_forearm_prt-binary.stl</uri>
          </mesh>
        </geometry>
      </collision>
      <visual name='r_forearm_visual'>
        <pose frame=''>0.296887 0 -0.079551 0 -0 0</pose>
        <geometry>
          <mesh>
            <scale>0.001 0.001 0.001</scale>
            <uri>model://iCub/meshes/simmechanics/sim_sea_2-5_r_forearm_prt-binary.stl</uri>
          </mesh>
        </geometry>
      </visual>
    </link>
    <joint name='r_wrist_prosup' type='revolute'>
      <child>r_forearm</child>
      <parent>r_elbow_1</parent>
      <axis>
        <xyz>0 0 1</xyz>
        <limit>
          <lower>-1.0472</lower>
          <upper>1.0472</upper>
          <effort>50000</effort>
          <velocity>50000</velocity>
        </limit>
        <dynamics>
          <damping>0.06</damping>
          <friction>0</friction>
          <spring_reference>0</spring_reference>
          <spring_stiffness>0</spring_stiffness>
        </dynamics>
        <use_parent_model_frame>1</use_parent_model_frame>
      </axis>
      <physics>
        <ode>
          <implicit_spring_damper>1</implicit_spring_damper>
          <cfm_damping>1</cfm_damping>
          <limit>
            <cfm>0</cfm>
            <erp>0.2</erp>
          </limit>
        </ode>
      </physics>
    </joint>
    <link name='r_wrist_1'>
      <pose frame=''>-0.00817 0.109398 -0.12656 -3.14159 -1.309 -3.14159</pose>
      <inertial>
        <pose frame=''>0.000986 -0.001176 0.004101 0 -0 0</pose>
        <mass>0.0362615</mass>
        <inertia>
          <ixx>0.01</ixx>
          <ixy>0</ixy>
          <ixz>0</ixz>
          <iyy>0.01</iyy>
          <iyz>0</iyz>
          <izz>0.01</izz>
        </inertia>
      </inertial>
      <collision name='r_wrist_1_collision'>
        <pose frame=''>0.400392 -7e-06 -0.104748 0 -0 0</pose>
        <geometry>
          <mesh>
            <scale>0.001 0.001 0.001</scale>
            <uri>model://iCub/meshes/simmechanics/sim_sea_2-5_r_wrist_pitch_prt-binary.stl</uri>
          </mesh>
        </geometry>
      </collision>
      <visual name='r_wrist_1_visual'>
        <pose frame=''>0.400392 -7e-06 -0.104748 0 -0 0</pose>
        <geometry>
          <mesh>
            <scale>0.001 0.001 0.001</scale>
            <uri>model://iCub/meshes/simmechanics/sim_sea_2-5_r_wrist_pitch_prt-binary.stl</uri>
          </mesh>
        </geometry>
      </visual>
    </link>
    <joint name='r_wrist_pitch' type='revolute'>
      <child>r_wrist_1</child>
      <parent>r_forearm</parent>
      <axis>
        <xyz>-1 -0 0</xyz>
        <limit>
          <lower>-1.39626</lower>
          <upper>0.436332</upper>
          <effort>50000</effort>
          <velocity>50000</velocity>
        </limit>
        <dynamics>
          <damping>0.06</damping>
          <friction>0</friction>
          <spring_reference>0</spring_reference>
          <spring_stiffness>0</spring_stiffness>
        </dynamics>
        <use_parent_model_frame>1</use_parent_model_frame>
      </axis>
      <physics>
        <ode>
          <implicit_spring_damper>1</implicit_spring_damper>
          <cfm_damping>1</cfm_damping>
          <limit>
            <cfm>0</cfm>
            <erp>0.2</erp>
          </limit>
        </ode>
      </physics>
    </joint>
    <link name='r_hand'>
      <pose frame=''>-0.01062 0.089898 -0.12656 -3.14159 -1.309 -3.14159</pose>
      <inertial>
        <pose frame=''>-0.064668 0.0056 0.022681 0 -0 0</pose>
        <mass>0.248289</mass>
        <inertia>
          <ixx>0.01</ixx>
          <ixy>0</ixy>
          <ixz>0</ixz>
          <iyy>0.01</iyy>
          <iyz>0</iyz>
          <izz>0.01</izz>
        </inertia>
      </inertial>
      <collision name='r_hand_collision'>
        <pose frame=''>0.399758 0.019493 -0.107115 0 -0 0</pose>
        <geometry>
          <mesh>
            <scale>0.001 0.001 0.001</scale>
            <uri>model://iCub/meshes/simmechanics/sim_sea_2-5_r_hand_prt-binary.stl</uri>
          </mesh>
        </geometry>
      </collision>
      <visual name='r_hand_visual'>
        <pose frame=''>0.399758 0.019493 -0.107115 0 -0 0</pose>
        <geometry>
          <mesh>
            <scale>0.001 0.001 0.001</scale>
            <uri>model://iCub/meshes/simmechanics/sim_sea_2-5_r_hand_prt-binary.stl</uri>
          </mesh>
        </geometry>
      </visual>
    </link>
    <joint name='r_wrist_yaw' type='revolute'>
      <child>r_hand</child>
      <parent>r_wrist_1</parent>
      <axis>
        <xyz>-0 1 -0</xyz>
        <limit>
          <lower>-0.349066</lower>
          <upper>0.436332</upper>
          <effort>50000</effort>
          <velocity>50000</velocity>
        </limit>
        <dynamics>
          <damping>0.06</damping>
          <friction>0</friction>
          <spring_reference>0</spring_reference>
          <spring_stiffness>0</spring_stiffness>
        </dynamics>
        <use_parent_model_frame>1</use_parent_model_frame>
      </axis>
    </joint>
    <static>0</static>
    <plugin name='controlboard_torso' filename='libgazebo_yarp_controlboard.so'>
      <yarpConfigurationFile>model://iCub/conf/gazebo_icub_torso.ini</yarpConfigurationFile>
    </plugin>
    <plugin name='controlboard_head_without_eyes' filename='libgazebo_yarp_controlboard.so'>
      <yarpConfigurationFile>model://iCub/conf/gazebo_icub_head_without_eyes.ini</yarpConfigurationFile>
    </plugin>
    <plugin name='controlboard_left_arm_no_hand' filename='libgazebo_yarp_controlboard.so'>
      <yarpConfigurationFile>model://iCub/conf/gazebo_icub_left_arm_no_hand_for_no_hand_model.ini</yarpConfigurationFile>
      <initialConfiguration>-0.52 0.52 0 0.785 0 0 0.698</initialConfiguration>
    </plugin>
    <plugin name='controlboard_right_arm_no_hand' filename='libgazebo_yarp_controlboard.so'>
      <yarpConfigurationFile>model://iCub/conf/gazebo_icub_right_arm_no_hand_for_no_hand_model.ini</yarpConfigurationFile>
      <initialConfiguration>-0.52 0.52 0 0.785 0 0 0.698</initialConfiguration>
    </plugin>
    <plugin name='controlboard_right_leg' filename='libgazebo_yarp_controlboard.so'>
      <yarpConfigurationFile>model://iCub/conf/gazebo_icub_right_leg.ini</yarpConfigurationFile>
    </plugin>
    <plugin name='controlboard_left_leg' filename='libgazebo_yarp_controlboard.so'>
      <yarpConfigurationFile>model://iCub/conf/gazebo_icub_left_leg.ini</yarpConfigurationFile>
    </plugin>
    <plugin name='apply_external_wrench' filename='libgazebo_yarp_externalwrench.so'>
      <robotNamefromConfigFile>model://iCub/conf/gazebo_icub_robotname.ini</robotNamefromConfigFile>
    </plugin>
  </model>
</sdf>
