<robot name="iCub">
  <link name="root_link">
    <inertial>
      <origin xyz="0.0248821 0.000103947 -0.0440806" rpy="1.57079632679 0 -1.57079632679"/>
      <mass value="5.09143"/>
      <inertia ixx="0.0139679" ixy="-5.93488e-06" ixz="-1.55458e-05" iyy="0.0202112" iyz="-0.00170968" izz="0.0249124"/>
    </inertial>
    <visual>
      <origin xyz="-0.0364 0 0.032" rpy="1.57079632679 0 -1.57079632679"/>
      <geometry>
        <mesh filename="package://iCub/meshes/simmechanics/sim_sea_2-5_root_link_prt-binary.stl" scale="0.001 0.001 0.001"/>
      </geometry>
      <material name="green">
        <color rgba="0 1 0 1"/>
      </material>
    </visual>
    <collision>
      <origin xyz="-0.0364 0 0.032" rpy="1.57079632679 0 -1.57079632679"/>
      <geometry>
        <mesh filename="package://iCub/meshes/simmechanics/sim_sea_2-5_root_link_prt-binary.stl" scale="0.001 0.001 0.001"/>
      </geometry>
    </collision>
  </link>
  <link name="r_hip_1">
    <inertial>
      <origin xyz="-0.040711 -5.9e-05 -0.0005234" rpy="0 0 0"/>
      <mass value="0.920101"/>
      <inertia ixx="0.000411114" ixy="-3.6672e-06" ixz="3.58037e-07" iyy="0.000576521" iyz="-2.19976e-06" izz="0.000587325"/>
    </inertial>
    <visual>
      <origin xyz="0.0233655 0.151913 0.0428515000001" rpy="0 0 0"/>
      <geometry>
        <mesh filename="package://iCub/meshes/simmechanics/sim_sea_2-5_r_hip_1_prt-binary.stl" scale="0.001 0.001 0.001"/>
      </geometry>
      <material name="black">
        <color rgba="0 0 0 1"/>
      </material>
    </visual>
    <collision>
      <origin xyz="0.0233655 0.151913 0.0428515000001" rpy="0 0 0"/>
      <geometry>
        <mesh filename="package://iCub/meshes/simmechanics/sim_sea_2-5_r_hip_1_prt-binary.stl" scale="0.001 0.001 0.001"/>
      </geometry>
    </collision>
  </link>
  <joint name="r_hip_pitch" type="revolute">
    <origin xyz="0.0064515 0.0233655 -0.119913" rpy="1.57079632679 0 -1.57079632679"/>
    <axis xyz="-1.0 0.0 0.0"/>
    <parent link="root_link"/>
    <child link="r_hip_1"/>
    <limit effort="50000" lower="-0.523598775598" upper="1.4835298642" velocity="50000"/>
    <dynamics damping="0.223"/>
  </joint>
  <link name="r_hip_2">
    <inertial>
      <origin xyz="3.49999999999e-06 -0.044233 0.0248982" rpy="0 0 0"/>
      <mass value="0.4194"/>
      <inertia ixx="0.01" ixy="0" ixz="0" iyy="0.01" iyz="0" izz="0.01"/>
    </inertial>
    <visual>
      <origin xyz="0.0701 0.151913 0.0691961998094" rpy="0 0 0"/>
      <geometry>
        <mesh filename="package://iCub/meshes/simmechanics/sim_sea_2-5_r_hip_2_prt-binary.stl" scale="0.001 0.001 0.001"/>
      </geometry>
      <material name="red">
        <color rgba="1 0 0 1"/>
      </material>
    </visual>
    <collision>
      <origin xyz="0.0701 0.151913 0.0691961998094" rpy="0 0 0"/>
      <geometry>
        <mesh filename="package://iCub/meshes/simmechanics/sim_sea_2-5_r_hip_2_prt-binary.stl" scale="0.001 0.001 0.001"/>
      </geometry>
    </collision>
  </link>
  <joint name="r_hip_roll" type="revolute">
    <origin xyz="-0.0467345 0 -0.0263447" rpy="0 0 0"/>
    <axis xyz="0.0 0.0 -1.0"/>
    <parent link="r_hip_1"/>
    <child link="r_hip_2"/>
    <limit effort="50000" lower="-0.261799" upper="1.482777778" velocity="50000"/>
    <dynamics damping="0.223"/>
  </joint>
  <link name="r_hip_3">
    <inertial>
      <origin xyz="-0.000123 -0.0002823 0.008718" rpy="-1.57079632679 0 -1.57079632679"/>
      <mass value="0.126212"/>
      <inertia ixx="0.01" ixy="0" ixz="0" iyy="0.01" iyz="0" izz="0.01"/>
    </inertial>
    <visual>
      <origin xyz="0.0437089998094 -0.0701 -0.226213" rpy="-1.57079632679 0 -1.57079632679"/>
      <geometry>
        <mesh filename="package://iCub/meshes/simmechanics/sim_sea_2-5_r_upper_thigh_prt-binary.stl" scale="0.001 0.001 0.001"/>
      </geometry>
      <material name="blue">
        <color rgba="0 0 1 1"/>
      </material>
    </visual>
    <collision>
      <origin xyz="0.0437089998094 -0.0701 -0.226213" rpy="-1.57079632679 0 -1.57079632679"/>
      <geometry>
        <mesh filename="package://iCub/meshes/simmechanics/sim_sea_2-5_r_upper_thigh_prt-binary.stl" scale="0.001 0.001 0.001"/>
      </geometry>
    </collision>
  </link>
  <joint name="r_leg_ft_sensor" type="fixed">
    <origin xyz="0 -0.0743 0.0254872" rpy="1.57079632679 -1.57079632679 0"/>
    <parent link="r_hip_2"/>
    <child link="r_hip_3"/>
    <dynamics damping="0.1"/>
  </joint>
  <link name="r_upper_leg">
    <inertial>
      <origin xyz="-7.67e-05 -0.078866 0.0033612" rpy="0 0 0"/>
      <mass value="1.8035"/>
      <inertia ixx="0.00646378343182" ixy="0.000122685853522" ixz="4.94531545868e-06" iyy="0.00144539832219" iyz="-0.000137533175718" izz="0.00645582688618"/>
    </inertial>
    <visual>
      <origin xyz="0.0701 0.241013 0.0437089998094" rpy="0 0 0"/>
      <geometry>
        <mesh filename="package://iCub/meshes/simmechanics/sim_sea_2-5_r_thigh_prt-binary.stl" scale="0.001 0.001 0.001"/>
      </geometry>
      <material name="yellow">
        <color rgba="1 1 0 1"/>
      </material>
    </visual>
    <collision>
      <origin xyz="0.0701 0.241013 0.0437089998094" rpy="0 0 0"/>
      <geometry>
        <mesh filename="package://iCub/meshes/simmechanics/sim_sea_2-5_r_thigh_prt-binary.stl" scale="0.001 0.001 0.001"/>
      </geometry>
    </collision>
  </link>
  <joint name="r_hip_yaw" type="revolute">
    <origin xyz="0 0 0.0146" rpy="-1.57079632679 0 -1.57079632679"/>
    <axis xyz="0.0 -1.0 0.0"/>
    <parent link="r_hip_3"/>
    <child link="r_upper_leg"/>
    <limit effort="50000" lower="-1.2217304764" upper="1.2217304764" velocity="50000"/>
    <dynamics damping="0.223"/>
  </joint>
  <link name="r_lower_leg">
    <inertial>
      <origin xyz="0.0060664 -0.088843 0.0011052" rpy="0 0 0"/>
      <mass value="1.472"/>
      <inertia ixx="0.00424220933661" ixy="0.000229531990172" ixz="-5.53606289926e-05" iyy="0.00151220835381" iyz="-0.000260873906634" izz="0.00457765110565"/>
    </inertial>
    <visual>
      <origin xyz="0.0797675001907 0.386638 0.0437089998093" rpy="0 0 0"/>
      <geometry>
        <mesh filename="package://iCub/meshes/simmechanics/sim_sea_2-5_r_shank_prt-binary.stl" scale="0.001 0.001 0.001"/>
      </geometry>
      <material name="pink">
        <color rgba="1 0 1 1"/>
      </material>
    </visual>
    <collision>
      <origin xyz="0.0797675001907 0.386638 0.0437089998093" rpy="0 0 0"/>
      <geometry>
        <mesh filename="package://iCub/meshes/simmechanics/sim_sea_2-5_r_shank_prt-binary.stl" scale="0.001 0.001 0.001"/>
      </geometry>
    </collision>
  </link>
  <joint name="r_knee" type="revolute">
    <origin xyz="-0.0096675 -0.145625 0" rpy="0 0 0"/>
    <axis xyz="-1.0 0.0 0.0"/>
    <parent link="r_upper_leg"/>
    <child link="r_lower_leg"/>
    <limit effort="50000" lower="-1.74532925199" upper="0.0" velocity="50000"/>
    <dynamics damping="0.223"/>
  </joint>
  <link name="r_ankle_1">
    <inertial>
      <origin xyz="0.0276282 6.29999999999e-05 0.0152507" rpy="0 0 0"/>
      <mass value="0.6803"/>
      <inertia ixx="0.01" ixy="0" ixz="0" iyy="0.01" iyz="0" izz="0.01"/>
    </inertial>
    <visual>
      <origin xyz="0.0986000001907 0.587138 0.0437089998093" rpy="0 0 0"/>
      <geometry>
        <mesh filename="package://iCub/meshes/simmechanics/sim_sea_2-5_r_ankle_prt-binary.stl" scale="0.001 0.001 0.001"/>
      </geometry>
      <material name="cyan">
        <color rgba="0 1 1 1"/>
      </material>
    </visual>
    <collision>
      <origin xyz="0.0986000001907 0.587138 0.0437089998093" rpy="0 0 0"/>
      <geometry>
        <mesh filename="package://iCub/meshes/simmechanics/sim_sea_2-5_r_ankle_prt-binary.stl" scale="0.001 0.001 0.001"/>
      </geometry>
    </collision>
  </link>
  <joint name="r_ankle_pitch" type="revolute">
    <origin xyz="-0.0188325 -0.2005 0" rpy="0 0 0"/>
    <axis xyz="1.0 0.0 0.0"/>
    <parent link="r_lower_leg"/>
    <child link="r_ankle_1"/>
    <limit effort="50000" lower="-0.523598775598" upper="0.523598775598" velocity="50000"/>
    <dynamics damping="0.223"/>
  </joint>
  <link name="r_ankle_2">
    <inertial>
      <origin xyz="-8.2e-06 -0.038202 0.0192673" rpy="0 0 0"/>
      <mass value="0.267485"/>
      <inertia ixx="0.01" ixy="0" ixz="0" iyy="0.01" iyz="0" izz="0.01"/>
    </inertial>
    <visual>
      <origin xyz="0.0701000001907 0.587138 0.0622089996185" rpy="0 0 0"/>
      <geometry>
        <mesh filename="package://iCub/meshes/simmechanics/sim_sea_2-5_r_foot_prt-binary.stl" scale="0.001 0.001 0.001"/>
      </geometry>
      <material name="green"/>
    </visual>
    <collision>
      <origin xyz="0.0701000001907 0.587138 0.0622089996185" rpy="0 0 0"/>
      <geometry>
        <mesh filename="package://iCub/meshes/simmechanics/sim_sea_2-5_r_foot_prt-binary.stl" scale="0.001 0.001 0.001"/>
      </geometry>
    </collision>
  </link>
  <joint name="r_ankle_roll" type="revolute">
    <origin xyz="0.0285 0 -0.0185" rpy="0 0 0"/>
    <axis xyz="0.0 0.0 -1.0"/>
    <parent link="r_ankle_1"/>
    <child link="r_ankle_2"/>
    <limit effort="50000" lower="-0.349065850399" upper="0.349065850399" velocity="50000"/>
    <dynamics damping="0.223"/>
  </joint>
  <link name="r_foot">
    <inertial>
      <origin xyz="0.0336237 0.0053646 -0.001138" rpy="-1.57079632679 0 -1.57079632679"/>
      <mass value="0.38227"/>
      <inertia ixx="0.00120765" ixy="3.70545e-07" ixz="-5.78137e-05" iyy="0.00141242" iyz="-7.82502e-06" izz="0.000273419"/>
    </inertial>
    <visual>
      <origin xyz="0.0472089996185 -0.0701000001907 -0.647438" rpy="-1.57079632679 0 -1.57079632679"/>
      <geometry>
        <mesh filename="package://iCub/meshes/simmechanics/sim_sea_2-5_r_sole_prt-binary.stl" scale="0.001 0.001 0.001"/>
      </geometry>
      <material name="white">
        <color rgba="1 1 1 1"/>
      </material>
    </visual>
    <collision>
      <origin xyz="0.0472089996185 -0.0701000001907 -0.647438" rpy="-1.57079632679 0 -1.57079632679"/>
      <geometry>
        <mesh filename="package://iCub/meshes/simmechanics/sim_sea_2-5_r_sole_prt-binary.stl" scale="0.001 0.001 0.001"/>
      </geometry>
    </collision>
  </link>
  <joint name="r_foot_ft_sensor" type="fixed">
    <origin xyz="0 -0.0603 0.015" rpy="1.57079632679 -1.57079632679 0"/>
    <parent link="r_ankle_2"/>
    <child link="r_foot"/>
    <dynamics damping="0.1"/>
  </joint>
  <link name="r_sole"/>
  <joint name="r_sole_fixed_joint" type="fixed">
    <origin xyz="0.0035 0 0.004" rpy="-3.14159265359 0 0"/>
    <parent link="r_foot"/>
    <child link="r_sole"/>
    <dynamics damping="0.1"/>
  </joint>
  <link name="l_hip_1">
    <inertial>
      <origin xyz="0.041678 -6.3e-05 -0.0004013" rpy="0 0 0"/>
      <mass value="0.915608"/>
      <inertia ixx="0.000402555" ixy="1.07708e-06" ixz="-1.569e-06" iyy="0.000570806" iyz="-6.5378e-07" izz="0.00057937"/>
    </inertial>
    <visual>
      <origin xyz="-0.0223861 0.151913 0.0428515000001" rpy="0 0 0"/>
      <geometry>
        <mesh filename="package://iCub/meshes/simmechanics/sim_sea_2-5_l_hip_1_prt-binary.stl" scale="0.001 0.001 0.001"/>
      </geometry>
      <material name="dblue">
        <color rgba="0 0 0.8 1"/>
      </material>
    </visual>
    <collision>
      <origin xyz="-0.0223861 0.151913 0.0428515000001" rpy="0 0 0"/>
      <geometry>
        <mesh filename="package://iCub/meshes/simmechanics/sim_sea_2-5_l_hip_1_prt-binary.stl" scale="0.001 0.001 0.001"/>
      </geometry>
    </collision>
  </link>
  <joint name="l_hip_pitch" type="revolute">
    <origin xyz="0.0064515 -0.0223861 -0.119913" rpy="1.57079632679 0 -1.57079632679"/>
    <axis xyz="-1.0 0.0 0.0"/>
    <parent link="root_link"/>
    <child link="l_hip_1"/>
    <limit effort="50000" lower="-0.523598775598" upper="1.4835298642" velocity="50000"/>
    <dynamics damping="0.223"/>
  </joint>
  <link name="l_hip_2">
    <inertial>
      <origin xyz="-1.94e-05 -0.044047 0.0239587" rpy="0 0 0"/>
      <mass value="0.421161"/>
      <inertia ixx="0.01" ixy="0" ixz="0" iyy="0.01" iyz="0" izz="0.01"/>
    </inertial>
    <visual>
      <origin xyz="-0.0701 0.151913 0.0683914998093" rpy="0 0 0"/>
      <geometry>
        <mesh filename="package://iCub/meshes/simmechanics/sim_sea_2-5_l_hip_2_prt-binary.stl" scale="0.001 0.001 0.001"/>
      </geometry>
      <material name="dgreen">
        <color rgba="0.1 0.8 0.1 1"/>
      </material>
    </visual>
    <collision>
      <origin xyz="-0.0701 0.151913 0.0683914998093" rpy="0 0 0"/>
      <geometry>
        <mesh filename="package://iCub/meshes/simmechanics/sim_sea_2-5_l_hip_2_prt-binary.stl" scale="0.001 0.001 0.001"/>
      </geometry>
    </collision>
  </link>
  <joint name="l_hip_roll" type="revolute">
    <origin xyz="0.0477139 0 -0.02554" rpy="0 0 0"/>
    <axis xyz="0.0 0.0 1.0"/>
    <parent link="l_hip_1"/>
    <child link="l_hip_2"/>
    <limit effort="50000" lower="-0.261799" upper="1.482777778" velocity="50000"/>
    <dynamics damping="0.223"/>
  </joint>
  <link name="l_hip_3">
    <inertial>
      <origin xyz="0.0002823 -0.0001229 0.008718" rpy="-1.57079632679 0 0"/>
      <mass value="0.126212"/>
      <inertia ixx="0.01" ixy="0" ixz="0" iyy="0.01" iyz="0" izz="0.01"/>
    </inertial>
    <visual>
      <origin xyz="-0.0701 0.043709 -0.226213" rpy="-1.57079632679 0 0"/>
      <geometry>
        <mesh filename="package://iCub/meshes/simmechanics/sim_sea_2-5_l_upper_thigh_prt-binary.stl" scale="0.001 0.001 0.001"/>
      </geometry>
      <material name="gray">
        <color rgba="0.5 0.5 0.5 1"/>
      </material>
    </visual>
    <collision>
      <origin xyz="-0.0701 0.043709 -0.226213" rpy="-1.57079632679 0 0"/>
      <geometry>
        <mesh filename="package://iCub/meshes/simmechanics/sim_sea_2-5_l_upper_thigh_prt-binary.stl" scale="0.001 0.001 0.001"/>
      </geometry>
    </collision>
  </link>
  <joint name="l_leg_ft_sensor" type="fixed">
    <origin xyz="0 -0.0743 0.0246825" rpy="1.57079632679 -1.57079632679 0"/>
    <parent link="l_hip_2"/>
    <child link="l_hip_3"/>
    <dynamics damping="0.1"/>
  </joint>
  <link name="l_upper_leg">
    <inertial>
      <origin xyz="0.0001504 -0.078827 0.0033485" rpy="0 0 0"/>
      <mass value="1.8084"/>
      <inertia ixx="0.00647124065718" ixy="-0.000117510769467" ixz="-3.57294757981e-06" iyy="0.00144843621276" iyz="-0.000137708519804" izz="0.00646464360719"/>
    </inertial>
    <visual>
      <origin xyz="-0.0701 0.241013 0.0437089998093" rpy="0 0 0"/>
      <geometry>
        <mesh filename="package://iCub/meshes/simmechanics/sim_sea_2-5_l_thigh_prt-binary.stl" scale="0.001 0.001 0.001"/>
      </geometry>
      <material name="green"/>
    </visual>
    <collision>
      <origin xyz="-0.0701 0.241013 0.0437089998093" rpy="0 0 0"/>
      <geometry>
        <mesh filename="package://iCub/meshes/simmechanics/sim_sea_2-5_l_thigh_prt-binary.stl" scale="0.001 0.001 0.001"/>
      </geometry>
    </collision>
  </link>
  <joint name="l_hip_yaw" type="revolute">
    <origin xyz="0 0 0.0146" rpy="-1.57079632679 0 -1.57079632679"/>
    <axis xyz="0.0 1.0 0.0"/>
    <parent link="l_hip_3"/>
    <child link="l_upper_leg"/>
    <limit effort="50000" lower="-1.2217304764" upper="1.2217304764" velocity="50000"/>
    <dynamics damping="0.223"/>
  </joint>
  <link name="l_lower_leg">
    <inertial>
      <origin xyz="0.0171669 -0.088615 0.000868" rpy="0 0 0"/>
      <mass value="1.4724"/>
      <inertia ixx="0.00423934701934" ixy="-0.000240090908858" ixz="6.75754833624e-05" iyy="0.00151341335811" iyz="-0.000229787246191" izz="0.00457420033003"/>
    </inertial>
    <visual>
      <origin xyz="-0.0565145001907 0.386638 0.0437089998093" rpy="0 0 0"/>
      <geometry>
        <mesh filename="package://iCub/meshes/simmechanics/sim_sea_2-5_l_shank_prt-binary.stl" scale="0.001 0.001 0.001"/>
      </geometry>
      <material name="black"/>
    </visual>
    <collision>
      <origin xyz="-0.0565145001907 0.386638 0.0437089998093" rpy="0 0 0"/>
      <geometry>
        <mesh filename="package://iCub/meshes/simmechanics/sim_sea_2-5_l_shank_prt-binary.stl" scale="0.001 0.001 0.001"/>
      </geometry>
    </collision>
  </link>
  <joint name="l_knee" type="revolute">
    <origin xyz="-0.0135855 -0.145625 0" rpy="0 0 0"/>
    <axis xyz="-1.0 0.0 0.0"/>
    <parent link="l_upper_leg"/>
    <child link="l_lower_leg"/>
    <limit effort="50000" lower="-1.74532925199" upper="0.0" velocity="50000"/>
    <dynamics damping="0.223"/>
  </joint>
  <link name="l_ankle_1">
    <inertial>
      <origin xyz="-0.0261116 6.29999999999e-05 0.0152606" rpy="0 0 0"/>
      <mass value="0.6798"/>
      <inertia ixx="0.01" ixy="0" ixz="0" iyy="0.01" iyz="0" izz="0.01"/>
    </inertial>
    <visual>
      <origin xyz="-0.0971179001907 0.587138 0.043409" rpy="0 0 0"/>
      <geometry>
        <mesh filename="package://iCub/meshes/simmechanics/sim_sea_2-5_l_ankle_prt-binary.stl" scale="0.001 0.001 0.001"/>
      </geometry>
      <material name="red"/>
    </visual>
    <collision>
      <origin xyz="-0.0971179001907 0.587138 0.043409" rpy="0 0 0"/>
      <geometry>
        <mesh filename="package://iCub/meshes/simmechanics/sim_sea_2-5_l_ankle_prt-binary.stl" scale="0.001 0.001 0.001"/>
      </geometry>
    </collision>
  </link>
  <joint name="l_ankle_pitch" type="revolute">
    <origin xyz="0.0406034 -0.2005 0" rpy="0 0 0"/>
    <axis xyz="1.0 0.0 0.0"/>
    <parent link="l_lower_leg"/>
    <child link="l_ankle_1"/>
    <limit effort="50000" lower="-0.523598775598" upper="0.523598775598" velocity="50000"/>
    <dynamics damping="0.223"/>
  </joint>
  <link name="l_ankle_2">
    <inertial>
      <origin xyz="-8.19999999999e-06 -0.038202 -0.04732025" rpy="0 0 0"/>
      <mass value="0.267485"/>
      <inertia ixx="0.01" ixy="0" ixz="0" iyy="0.01" iyz="0" izz="0.01"/>
    </inertial>
    <visual>
      <origin xyz="-0.0701000001907 0.587138 -0.00467855" rpy="0 0 0"/>
      <geometry>
        <mesh filename="package://iCub/meshes/simmechanics/sim_sea_2-5_l_foot_prt-binary.stl" scale="0.001 0.001 0.001"/>
      </geometry>
      <material name="blue"/>
    </visual>
    <collision>
      <origin xyz="-0.0701000001907 0.587138 -0.00467855" rpy="0 0 0"/>
      <geometry>
        <mesh filename="package://iCub/meshes/simmechanics/sim_sea_2-5_l_foot_prt-binary.stl" scale="0.001 0.001 0.001"/>
      </geometry>
    </collision>
  </link>
  <joint name="l_ankle_roll" type="revolute">
    <origin xyz="-0.0270179 0 0.04808755" rpy="0 0 0"/>
    <axis xyz="0.0 0.0 1.0"/>
    <parent link="l_ankle_1"/>
    <child link="l_ankle_2"/>
    <limit effort="50000" lower="-0.349065850399" upper="0.349065850399" velocity="50000"/>
    <dynamics damping="0.223"/>
  </joint>
  <link name="l_foot">
    <inertial>
      <origin xyz="0.0336906 -0.0053662 -0.001154" rpy="-1.57079632679 0 -1.57079632679"/>
      <mass value="0.382372"/>
      <inertia ixx="0.00121061" ixy="-3.65345e-07" ixz="5.78649e-05" iyy="0.00141515" iyz="-7.67241e-06" izz="0.000273665"/>
    </inertial>
    <visual>
      <origin xyz="0.0472089996187 0.0701000001907 -0.647438" rpy="-1.57079632679 0 -1.57079632679"/>
      <geometry>
        <mesh filename="package://iCub/meshes/simmechanics/sim_sea_2-5_l_sole_prt-binary.stl" scale="0.001 0.001 0.001"/>
      </geometry>
      <material name="yellow"/>
    </visual>
    <collision>
      <origin xyz="0.0472089996187 0.0701000001907 -0.647438" rpy="-1.57079632679 0 -1.57079632679"/>
      <geometry>
        <mesh filename="package://iCub/meshes/simmechanics/sim_sea_2-5_l_sole_prt-binary.stl" scale="0.001 0.001 0.001"/>
      </geometry>
    </collision>
  </link>
  <joint name="l_foot_ft_sensor" type="fixed">
    <origin xyz="0 -0.0603 -0.05158755" rpy="1.57079632679 -1.57079632679 0"/>
    <parent link="l_ankle_2"/>
    <child link="l_foot"/>
    <dynamics damping="0.1"/>
  </joint>
  <link name="l_sole"/>
  <joint name="l_sole_fixed_joint" type="fixed">
    <origin xyz="0.0035 0 0.004" rpy="-3.14159265359 0 0"/>
    <parent link="l_foot"/>
    <child link="l_sole"/>
    <dynamics damping="0.1"/>
  </joint>
  <link name="torso_1">
    <inertial>
      <origin xyz="0.0270921359 0.02914798 -0.0004398" rpy="0 0 0"/>
      <mass value="0.67144"/>
      <inertia ixx="0.00040911" ixy="-1.04522e-06" ixz="-1.02516e-06" iyy="0.000384141" iyz="6.50708e-06" izz="0.000299445"/>
    </inertial>
    <visual>
      <origin xyz="0.0270462998093 0.032 0.0364" rpy="0 0 0"/>
      <geometry>
        <mesh filename="package://iCub/meshes/simmechanics/sim_sea_2-5_lap_belt_1_prt-binary.stl" scale="0.001 0.001 0.001"/>
      </geometry>
      <material name="pink"/>
    </visual>
    <collision>
      <origin xyz="0.0270462998093 0.032 0.0364" rpy="0 0 0"/>
      <geometry>
        <mesh filename="package://iCub/meshes/simmechanics/sim_sea_2-5_lap_belt_1_prt-binary.stl" scale="0.001 0.001 0.001"/>
      </geometry>
    </collision>
  </link>
  <joint name="torso_pitch" type="revolute">
    <origin xyz="0 0.0270463 0" rpy="1.57079632679 0 -1.57079632679"/>
    <axis xyz="1.0 0.0 0.0"/>
    <parent link="root_link"/>
    <child link="torso_1"/>
    <limit effort="50000" lower="-0.349065850399" upper="1.2217304764" velocity="50000"/>
    <dynamics damping="0.06"/>
  </joint>
  <link name="torso_2">
    <inertial>
      <origin xyz="-0.000113507809265 0.0361525 0.0570963" rpy="0 0 0"/>
      <mass value="0.425685"/>
      <inertia ixx="0.000829234" ixy="2.37006e-08" ixz="9.25231e-08" iyy="0.000436517" iyz="-1.74814e-07" izz="0.000604802"/>
    </inertial>
    <visual>
      <origin xyz="0 0.1433 0.0386531" rpy="0 0 0"/>
      <geometry>
        <mesh filename="package://iCub/meshes/simmechanics/sim_sea_2-5_lap_belt_2_prt-binary.stl" scale="0.001 0.001 0.001"/>
      </geometry>
      <material name="cyan"/>
    </visual>
    <collision>
      <origin xyz="0 0.1433 0.0386531" rpy="0 0 0"/>
      <geometry>
        <mesh filename="package://iCub/meshes/simmechanics/sim_sea_2-5_lap_belt_2_prt-binary.stl" scale="0.001 0.001 0.001"/>
      </geometry>
    </collision>
  </link>
  <joint name="torso_roll" type="revolute">
    <origin xyz="0.0270462998093 0.032 -0.0573446" rpy="0 0 0"/>
    <axis xyz="0.0 0.0 -1.0"/>
    <parent link="torso_1"/>
    <child link="torso_2"/>
    <limit effort="50000" lower="-0.523598775598" upper="0.523598775598" velocity="50000"/>
    <dynamics damping="0.06"/>
  </joint>
  <link name="chest">
    <inertial>
      <origin xyz="0.000188619190735 0.073091 -0.0472381" rpy="0 0 0"/>
      <mass value="7.638"/>
      <inertia ixx="0.0430324878618" ixy="2.91075388804e-05" ixz="0.000181985229949" iyy="0.0440835725548" iyz="-0.000429106409108" izz="0.0260563249911"/>
    </inertial>
    <visual>
      <origin xyz="0 0.0928 -0.024189" rpy="0 0 0"/>
      <geometry>
        <mesh filename="package://iCub/meshes/simmechanics/sim_sea_2-5_chest_bb_prt-binary.stl" scale="0.001 0.001 0.001"/>
      </geometry>
      <material name="green"/>
    </visual>
    <collision>
      <origin xyz="0 0.0928 -0.024189" rpy="0 0 0"/>
      <geometry>
        <mesh filename="package://iCub/meshes/simmechanics/sim_sea_2-5_chest_bb_prt-binary.stl" scale="0.001 0.001 0.001"/>
      </geometry>
    </collision>
  </link>
  <joint name="torso_yaw" type="revolute">
    <origin xyz="0 0.05 0.0628421" rpy="0 0 0"/>
    <axis xyz="0.0 -1.0 0.0"/>
    <parent link="torso_2"/>
    <child link="chest"/>
    <limit effort="50000" lower="-0.872664625997" upper="0.872664625997" velocity="50000"/>
    <dynamics damping="0.06"/>
  </joint>
  <link name="r_shoulder_1">
    <inertial>
      <origin xyz="-0.0122656014133 3.2e-05 -0.00321064290449" rpy="0 0 0"/>
      <mass value="0.114862"/>
      <inertia ixx="0.01" ixy="0" ixz="0" iyy="0.01" iyz="0" izz="0.01"/>
    </inertial>
    <visual>
      <origin xyz="0.0990079253076 0 -0.0265292487558" rpy="0 0 0"/>
      <geometry>
        <mesh filename="package://iCub/meshes/simmechanics/sim_sea_2-5_r_shoulder_1_prt-binary.stl" scale="0.001 0.001 0.001"/>
      </geometry>
      <material name="white"/>
    </visual>
    <collision>
      <origin xyz="0.0990079253076 0 -0.0265292487558" rpy="0 0 0"/>
      <geometry>
        <mesh filename="package://iCub/meshes/simmechanics/sim_sea_2-5_r_shoulder_1_prt-binary.stl" scale="0.001 0.001 0.001"/>
      </geometry>
    </collision>
  </link>
  <joint name="r_shoulder_pitch" type="revolute">
    <origin xyz="-0.120015999809 0.0928 0.0079693" rpy="0 -0.523598883792 3.14159265359"/>
    <axis xyz="-0.965925926173 0.0 0.258819275525"/>
    <parent link="chest"/>
    <child link="r_shoulder_1"/>
    <limit effort="50000" lower="-1.66678943565" upper="0.174532925199" velocity="50000"/>
    <dynamics damping="0.06"/>
  </joint>
  <link name="r_shoulder_2">
    <inertial>
      <origin xyz="-0.0214141709438 0.000271725272551 -0.0194402344535" rpy="0 0 0"/>
      <mass value="0.238162"/>
      <inertia ixx="0.01" ixy="0" ixz="0" iyy="0.01" iyz="0" izz="0.01"/>
    </inertial>
    <visual>
      <origin xyz="0.106587808568 2.31914715418e-07 -0.0407392121175" rpy="0 0 0"/>
      <geometry>
        <mesh filename="package://iCub/meshes/simmechanics/sim_sea_2-5_r_shoulder_2_prt-binary.stl" scale="0.001 0.001 0.001"/>
      </geometry>
      <material name="dblue"/>
    </visual>
    <collision>
      <origin xyz="0.106587808568 2.31914715418e-07 -0.0407392121175" rpy="0 0 0"/>
      <geometry>
        <mesh filename="package://iCub/meshes/simmechanics/sim_sea_2-5_r_shoulder_2_prt-binary.stl" scale="0.001 0.001 0.001"/>
      </geometry>
    </collision>
  </link>
  <joint name="r_shoulder_roll" type="revolute">
    <origin xyz="-0.00758046573227 0 0.0142102463639" rpy="-0.270597611583 -0.252680154648 -1.50155680035"/>
    <axis xyz="-0.258819 -2.77555756156e-17 -0.965926"/>
    <parent link="r_shoulder_1"/>
    <child link="r_shoulder_2"/>
    <limit effort="50000" lower="0.0" upper="2.80648943721" velocity="50000"/>
    <dynamics damping="0.06"/>
  </joint>
  <link name="r_shoulder_3">
    <inertial>
      <origin xyz="-0.0267620766871 -6.99999999998e-06 0.0146999207713" rpy="0 0 0"/>
      <mass value="0.35913"/>
      <inertia ixx="0.01" ixy="0" ixz="0" iyy="0.01" iyz="0" izz="0.01"/>
    </inertial>
    <visual>
      <origin xyz="0.131933879164 0 -0.0353515667647" rpy="0 0 0"/>
      <geometry>
        <mesh filename="package://iCub/meshes/simmechanics/sim_sea_2-5_r_upper_arm_prt-binary.stl" scale="0.001 0.001 0.001"/>
      </geometry>
      <material name="dgreen"/>
    </visual>
    <collision>
      <origin xyz="0.131933879164 0 -0.0353515667647" rpy="0 0 0"/>
      <geometry>
        <mesh filename="package://iCub/meshes/simmechanics/sim_sea_2-5_r_upper_arm_prt-binary.stl" scale="0.001 0.001 0.001"/>
      </geometry>
    </collision>
  </link>
  <joint name="r_shoulder_yaw" type="revolute">
    <origin xyz="-0.0253460713232 2.32750427306e-07 -0.00538764806457" rpy="-0.252689546175 0.0085186183214 0.067039889142"/>
    <axis xyz="0.965925843882 -2.22044604925e-16 -0.258818979447"/>
    <parent link="r_shoulder_2"/>
    <child link="r_shoulder_3"/>
    <limit effort="50000" lower="-0.645771823238" upper="1.3962634016" velocity="50000"/>
    <dynamics damping="0.06"/>
  </joint>
  <link name="r_upper_arm">
    <inertial>
      <origin xyz="-0.006087 0.000126 0.0293121" rpy="0 1.30899700697 0"/>
      <mass value="0.745104"/>
      <inertia ixx="0.000509527" ixy="1.19292e-06" ixz="-1.17426e-05" iyy="0.000668487" iyz="1.13363e-06" izz="0.000599254"/>
    </inertial>
    <visual>
      <origin xyz="-0.015 0 -0.1933" rpy="0 1.30899700697 0"/>
      <geometry>
        <mesh filename="package://iCub/meshes/simmechanics/sim_sea_2-5_r_elbow_prt-binary.stl" scale="0.001 0.001 0.001"/>
      </geometry>
      <material name="gray"/>
    </visual>
    <collision>
      <origin xyz="-0.015 0 -0.1933" rpy="0 1.30899700697 0"/>
      <geometry>
        <mesh filename="package://iCub/meshes/simmechanics/sim_sea_2-5_r_elbow_prt-binary.stl" scale="0.001 0.001 0.001"/>
      </geometry>
    </collision>
  </link>
  <joint name="r_arm_ft_sensor" type="fixed">
    <origin xyz="-0.0508973017665 0 0.0291670296206" rpy="0 -1.30899700697 0"/>
    <parent link="r_shoulder_3"/>
    <child link="r_upper_arm"/>
    <dynamics damping="0.1"/>
  </joint>
  <link name="r_elbow_1">
    <inertial>
      <origin xyz="-0.00673912932843 0.0188019 -0.00465769236154" rpy="0 0 0"/>
      <mass value="0.267903"/>
      <inertia ixx="0.01" ixy="0" ixz="0" iyy="0.01" iyz="0" izz="0.01"/>
    </inertial>
    <visual>
      <origin xyz="0.259390463317 0.0224999 -0.0850325886962" rpy="0 0 0"/>
      <geometry>
        <mesh filename="package://iCub/meshes/simmechanics/sim_sea_2-5_r_elbow_prosup_prt-binary.stl" scale="0.001 0.001 0.001"/>
      </geometry>
      <material name="green"/>
    </visual>
    <collision>
      <origin xyz="0.259390463317 0.0224999 -0.0850325886962" rpy="0 0 0"/>
      <geometry>
        <mesh filename="package://iCub/meshes/simmechanics/sim_sea_2-5_r_elbow_prosup_prt-binary.stl" scale="0.001 0.001 0.001"/>
      </geometry>
    </collision>
  </link>
  <joint name="r_elbow" type="revolute">
    <origin xyz="0 -0.0224999 0.07926" rpy="0 1.30899700697 0"/>
    <axis xyz="2.22044604925e-16 1.0 0.0"/>
    <parent link="r_upper_arm"/>
    <child link="r_elbow_1"/>
    <limit effort="50000" lower="0.261799387799" upper="1.85004900711" velocity="50000"/>
    <dynamics damping="0.06"/>
  </joint>
  <link name="r_forearm">
    <inertial>
      <origin xyz="-0.0404391133886 -0.000328 0.00532733448387" rpy="0 0 0"/>
      <mass value="0.6347"/>
      <inertia ixx="0.000370044" ixy="-1.65419e-06" ixz="0.00010538" iyy="0.000672279" iyz="1.1456e-06" izz="0.000553637"/>
    </inertial>
    <visual>
      <origin xyz="0.296886967375 0 -0.0795506015227" rpy="0 0 0"/>
      <geometry>
        <mesh filename="package://iCub/meshes/simmechanics/sim_sea_2-5_r_forearm_prt-binary.stl" scale="0.001 0.001 0.001"/>
      </geometry>
      <material name="black"/>
    </visual>
    <collision>
      <origin xyz="0.296886967375 0 -0.0795506015227" rpy="0 0 0"/>
      <geometry>
        <mesh filename="package://iCub/meshes/simmechanics/sim_sea_2-5_r_forearm_prt-binary.stl" scale="0.001 0.001 0.001"/>
      </geometry>
    </collision>
  </link>
  <joint name="r_wrist_prosup" type="revolute">
    <origin xyz="-0.0384624299027 0.0224999 -0.00522316819403" rpy="0 0 0"/>
    <axis xyz="0.965925843882 -2.22044604925e-16 -0.258818979447"/>
    <parent link="r_elbow_1"/>
    <child link="r_forearm"/>
    <limit effort="50000" lower="-1.0471975512" upper="1.0471975512" velocity="50000"/>
    <dynamics damping="0.06"/>
  </joint>
  <link name="r_forearm_skin_0"/>
  <joint name="r_forearm_skin_0_fixed_joint" type="fixed">
    <origin xyz="-0.0454493286618 0.030077 -0.00628656037901" rpy="1.69181522292 -0.271026744341 -3.06880438227"/>
    <parent link="r_forearm"/>
    <child link="r_forearm_skin_0"/>
    <dynamics damping="0.1"/>
  </joint>
  <link name="r_forearm_skin_1"/>
  <joint name="r_forearm_skin_1_fixed_joint" type="fixed">
    <origin xyz="-0.0333728935826 0.028826 -0.0198456867711" rpy="1.86694023278 -0.274442533764 -3.09946977984"/>
    <parent link="r_forearm"/>
    <child link="r_forearm_skin_1"/>
    <dynamics damping="0.1"/>
  </joint>
  <link name="r_forearm_skin_2"/>
  <joint name="r_forearm_skin_2_fixed_joint" type="fixed">
    <origin xyz="-0.0146988929852 0.031279 -0.0160117338371" rpy="1.72847287019 -0.264015219116 -3.12733260687"/>
    <parent link="r_forearm"/>
    <child link="r_forearm_skin_2"/>
    <dynamics damping="0.1"/>
  </joint>
  <link name="r_forearm_skin_3"/>
  <joint name="r_forearm_skin_3_fixed_joint" type="fixed">
    <origin xyz="-0.045567293622 -0.030891 -0.00633000929351" rpy="-1.69487280859 -0.269757727104 3.07959743574"/>
    <parent link="r_forearm"/>
    <child link="r_forearm_skin_3"/>
    <dynamics damping="0.1"/>
  </joint>
  <link name="r_forearm_skin_4"/>
  <joint name="r_forearm_skin_4_fixed_joint" type="fixed">
    <origin xyz="-0.0635326332996 -0.0281163 -0.00899784258066" rpy="-1.80734960194 -0.0393131796327 2.97997643632"/>
    <parent link="r_forearm"/>
    <child link="r_forearm_skin_4"/>
    <dynamics damping="0.1"/>
  </joint>
  <link name="r_forearm_skin_5"/>
  <joint name="r_forearm_skin_5_fixed_joint" type="fixed">
    <origin xyz="-0.0688211941968 -0.0179483 -0.0231133361791" rpy="-2.5410475806 -0.385627260642 3.05486989667"/>
    <parent link="r_forearm"/>
    <child link="r_forearm_skin_5"/>
    <dynamics damping="0.1"/>
  </joint>
  <link name="r_forearm_skin_6"/>
  <joint name="r_forearm_skin_6_fixed_joint" type="fixed">
    <origin xyz="-0.0333948436255 -0.0295479 -0.0198325583433" rpy="-1.86628164653 -0.272886336181 3.10448585021"/>
    <parent link="r_forearm"/>
    <child link="r_forearm_skin_6"/>
    <dynamics damping="0.1"/>
  </joint>
  <link name="r_forearm_skin_7"/>
  <joint name="r_forearm_skin_7_fixed_joint" type="fixed">
    <origin xyz="-0.0147224260074 -0.0319422 -0.0159326482703" rpy="-1.72564640857 -0.263992900722 3.12721254266"/>
    <parent link="r_forearm"/>
    <child link="r_forearm_skin_7"/>
    <dynamics damping="0.1"/>
  </joint>
  <link name="r_forearm_skin_8"/>
  <joint name="r_forearm_skin_8_fixed_joint" type="fixed">
    <origin xyz="-0.0228528628554 -0.0097862 -0.041885146375" rpy="-2.94801979137 -0.270605090512 3.13980557285"/>
    <parent link="r_forearm"/>
    <child link="r_forearm_skin_8"/>
    <dynamics damping="0.1"/>
  </joint>
  <link name="r_forearm_skin_9"/>
  <joint name="r_forearm_skin_9_fixed_joint" type="fixed">
    <origin xyz="-0.0376032734683 -0.018955 -0.0340163371186" rpy="-2.58406517708 -0.2933217196 3.12128407396"/>
    <parent link="r_forearm"/>
    <child link="r_forearm_skin_9"/>
    <dynamics damping="0.1"/>
  </joint>
  <link name="r_forearm_skin_10"/>
  <joint name="r_forearm_skin_10_fixed_joint" type="fixed">
    <origin xyz="-0.0542285210888 -0.0097861 -0.0321469082866" rpy="-2.94123313406 -0.328304471922 3.1276263754"/>
    <parent link="r_forearm"/>
    <child link="r_forearm_skin_10"/>
    <dynamics damping="0.1"/>
  </joint>
  <link name="r_forearm_skin_11"/>
  <joint name="r_forearm_skin_11_fixed_joint" type="fixed">
    <origin xyz="-0.0542240912024 0.009043 -0.0321431259452" rpy="2.93929835957 -0.329101389745 -3.12731916446"/>
    <parent link="r_forearm"/>
    <child link="r_forearm_skin_11"/>
    <dynamics damping="0.1"/>
  </joint>
  <link name="r_forearm_skin_12"/>
  <joint name="r_forearm_skin_12_fixed_joint" type="fixed">
    <origin xyz="-0.0375994633868 0.018216 -0.0340191179961" rpy="2.58303505964 -0.29483050207 -3.12026580314"/>
    <parent link="r_forearm"/>
    <child link="r_forearm_skin_12"/>
    <dynamics damping="0.1"/>
  </joint>
  <link name="r_forearm_skin_13"/>
  <joint name="r_forearm_skin_13_fixed_joint" type="fixed">
    <origin xyz="-0.0228550868405 0.009048 -0.0418919009209" rpy="2.94896679198 -0.270583947189 -3.13981880352"/>
    <parent link="r_forearm"/>
    <child link="r_forearm_skin_13"/>
    <dynamics damping="0.1"/>
  </joint>
  <link name="r_forearm_skin_14"/>
  <joint name="r_forearm_skin_14_fixed_joint" type="fixed">
    <origin xyz="-0.0687703276364 0.01716 -0.0230239558511" rpy="2.48044991868 -0.295542566281 -2.91877349139"/>
    <parent link="r_forearm"/>
    <child link="r_forearm_skin_14"/>
    <dynamics damping="0.1"/>
  </joint>
  <link name="r_forearm_skin_15"/>
  <joint name="r_forearm_skin_15_fixed_joint" type="fixed">
    <origin xyz="-0.0633786419662 0.027145 -0.00879405455544" rpy="1.80492769741 -0.289783281916 -3.02765891428"/>
    <parent link="r_forearm"/>
    <child link="r_forearm_skin_15"/>
    <dynamics damping="0.1"/>
  </joint>
  <link name="r_forearm_skin_16"/>
  <joint name="r_forearm_skin_16_fixed_joint" type="fixed">
    <origin xyz="-0.03792482187 0.030487 0.0206369503605" rpy="1.41280007026 -0.25082462139 -3.06572742343"/>
    <parent link="r_forearm"/>
    <child link="r_forearm_skin_16"/>
    <dynamics damping="0.1"/>
  </joint>
  <link name="r_forearm_skin_17"/>
  <joint name="r_forearm_skin_17_fixed_joint" type="fixed">
    <origin xyz="-0.0543170548821 0.027725 0.0303291240179" rpy="1.27223716205 -0.23059304703 -3.03195542837"/>
    <parent link="r_forearm"/>
    <child link="r_forearm_skin_17"/>
    <dynamics damping="0.1"/>
  </joint>
  <link name="r_forearm_skin_19"/>
  <joint name="r_forearm_skin_19_fixed_joint" type="fixed">
    <origin xyz="-0.0381266107138 -0.0312941 0.020690605393" rpy="-1.41560888703 -0.252569290226 3.07715217889"/>
    <parent link="r_forearm"/>
    <child link="r_forearm_skin_19"/>
    <dynamics damping="0.1"/>
  </joint>
  <link name="r_forearm_skin_22"/>
  <joint name="r_forearm_skin_22_fixed_joint" type="fixed">
    <origin xyz="-0.0544173950421 -0.0287223 0.0306037516609" rpy="-1.2658242728 -0.234328151379 3.04788317971"/>
    <parent link="r_forearm"/>
    <child link="r_forearm_skin_22"/>
    <dynamics damping="0.1"/>
  </joint>
  <link name="r_forearm_skin_24"/>
  <joint name="r_forearm_skin_24_fixed_joint" type="fixed">
    <origin xyz="-0.0700345319564 -0.0097164 0.050069108714" rpy="-0.23489327644 -0.0388172993982 3.08676345459"/>
    <parent link="r_forearm"/>
    <child link="r_forearm_skin_24"/>
    <dynamics damping="0.1"/>
  </joint>
  <link name="r_forearm_skin_25"/>
  <joint name="r_forearm_skin_25_fixed_joint" type="fixed">
    <origin xyz="-0.0535999216295 -0.0182238 0.0454698125045" rpy="-0.564295527715 -0.136980272197 3.05963182792"/>
    <parent link="r_forearm"/>
    <child link="r_forearm_skin_25"/>
    <dynamics damping="0.1"/>
  </joint>
  <link name="r_forearm_skin_28"/>
  <joint name="r_forearm_skin_28_fixed_joint" type="fixed">
    <origin xyz="-0.0535859272148 0.017412 0.045352037397" rpy="0.59077064408 -0.0531607226063 3.10597081167"/>
    <parent link="r_forearm"/>
    <child link="r_forearm_skin_28"/>
    <dynamics damping="0.1"/>
  </joint>
  <link name="r_forearm_skin_29"/>
  <joint name="r_forearm_skin_29_fixed_joint" type="fixed">
    <origin xyz="-0.0700355805031 0.008954 0.0500111036233" rpy="0.248630982209 -0.0383136556786 -3.08328999116"/>
    <parent link="r_forearm"/>
    <child link="r_forearm_skin_29"/>
    <dynamics damping="0.1"/>
  </joint>
  <link name="r_forearm_dh_frame"/>
  <joint name="r_forearm_dh_frame_fixed_joint" type="fixed">
    <origin xyz="-0.102871102373 7.00000000002e-06 0.0275642213111" rpy="-0.261799319827 0 -1.57079632679"/>
    <parent link="r_forearm"/>
    <child link="r_forearm_dh_frame"/>
    <dynamics damping="0.1"/>
  </joint>
  <link name="r_wrist_1">
    <inertial>
      <origin xyz="0.000986101955547 -0.001176 0.00410132736724" rpy="0 0 0"/>
      <mass value="0.0362615"/>
      <inertia ixx="0.01" ixy="0" ixz="0" iyy="0.01" iyz="0" izz="0.01"/>
    </inertial>
    <visual>
      <origin xyz="0.400392176248 -7.00000000009e-06 -0.104748304516" rpy="0 0 0"/>
      <geometry>
        <mesh filename="package://iCub/meshes/simmechanics/sim_sea_2-5_r_wrist_pitch_prt-binary.stl" scale="0.001 0.001 0.001"/>
      </geometry>
      <material name="red"/>
    </visual>
    <collision>
      <origin xyz="0.400392176248 -7.00000000009e-06 -0.104748304516" rpy="0 0 0"/>
      <geometry>
        <mesh filename="package://iCub/meshes/simmechanics/sim_sea_2-5_r_wrist_pitch_prt-binary.stl" scale="0.001 0.001 0.001"/>
      </geometry>
    </collision>
  </link>
  <joint name="r_wrist_pitch" type="revolute">
    <origin xyz="-0.103505208873 7.00000000002e-06 0.0251977029936" rpy="0 0 0"/>
    <axis xyz="0.258818979447 0.0 0.965925843882"/>
    <parent link="r_forearm"/>
    <child link="r_wrist_1"/>
    <limit effort="50000" lower="-1.3962634016" upper="0.436332312999" velocity="50000"/>
    <dynamics damping="0.06"/>
  </joint>
  <link name="r_hand">
    <inertial>
      <origin xyz="-0.064668163717 0.0056002 0.0226812940918" rpy="0 0 0"/>
      <mass value="0.248289"/>
      <inertia ixx="0.01" ixy="0" ixz="0" iyy="0.01" iyz="0" izz="0.01"/>
    </inertial>
    <visual>
      <origin xyz="0.399758069749 0.0194929 -0.107114822834" rpy="0 0 0"/>
      <geometry>
        <mesh filename="package://iCub/meshes/simmechanics/sim_sea_2-5_r_hand_prt-binary.stl" scale="0.001 0.001 0.001"/>
      </geometry>
      <material name="blue"/>
    </visual>
    <collision>
      <origin xyz="0.399758069749 0.0194929 -0.107114822834" rpy="0 0 0"/>
      <geometry>
        <mesh filename="package://iCub/meshes/simmechanics/sim_sea_2-5_r_hand_prt-binary.stl" scale="0.001 0.001 0.001"/>
      </geometry>
    </collision>
  </link>
  <joint name="r_wrist_yaw" type="revolute">
    <origin xyz="0.000634106499644 -0.0194999 0.00236651831751" rpy="0 0 0"/>
    <axis xyz="2.22044604925e-16 1.0 0.0"/>
    <parent link="r_wrist_1"/>
    <child link="r_hand"/>
    <limit effort="50000" lower="-0.349065850399" upper="0.436332312999" velocity="50000"/>
    <dynamics damping="0.06"/>
  </joint>
  <link name="r_hand_dh_frame"/>
  <joint name="r_hand_dh_frame_fixed_joint" type="fixed">
    <origin xyz="-0.0576542978428 -0.0055568 0.0136938323083" rpy="-1.57079632679 -0.261799319827 3.14159265359"/>
    <parent link="r_hand"/>
    <child link="r_hand_dh_frame"/>
    <dynamics damping="0.1"/>
  </joint>
  <link name="l_shoulder_1">
    <inertial>
      <origin xyz="-0.008985 -3.3e-05 -0.0088998" rpy="0 0 0"/>
      <mass value="0.114882"/>
      <inertia ixx="0.01" ixy="0" ixz="0" iyy="0.01" iyz="0" izz="0.01"/>
    </inertial>
    <visual>
      <origin xyz="-0.120257482 0 -0.032223" rpy="0 0 0"/>
      <geometry>
        <mesh filename="package://iCub/meshes/simmechanics/sim_sea_2-5_l_shoulder_1_prt-binary.stl" scale="0.001 0.001 0.001"/>
      </geometry>
      <material name="yellow"/>
    </visual>
    <collision>
      <origin xyz="-0.120257482 0 -0.032223" rpy="0 0 0"/>
      <geometry>
        <mesh filename="package://iCub/meshes/simmechanics/sim_sea_2-5_l_shoulder_1_prt-binary.stl" scale="0.001 0.001 0.001"/>
      </geometry>
    </collision>
  </link>
  <joint name="l_shoulder_pitch" type="revolute">
    <origin xyz="0.120016000191 0.0928 0.0079693" rpy="0 0 0"/>
    <axis xyz="0.965926 0.0 0.258819"/>
    <parent link="chest"/>
    <child link="l_shoulder_1"/>
    <limit effort="50000" lower="-1.66678943565" upper="0.174532925199" velocity="50000"/>
    <dynamics damping="0.06"/>
  </joint>
  <link name="l_shoulder_2">
    <inertial>
      <origin xyz="0.0214745951272 0.000268957899687 -0.0194107361535" rpy="0 0 0"/>
      <mass value="0.238162"/>
      <inertia ixx="0.01" ixy="0" ixz="0" iyy="0.01" iyz="0" izz="0.01"/>
    </inertial>
    <visual>
      <origin xyz="-0.106586691581 1.10800934344e-07 -0.040743380771" rpy="0 0 0"/>
      <geometry>
        <mesh filename="package://iCub/meshes/simmechanics/sim_sea_2-5_l_shoulder_2_prt-binary.stl" scale="0.001 0.001 0.001"/>
      </geometry>
      <material name="pink"/>
    </visual>
    <collision>
      <origin xyz="-0.106586691581 1.10800934344e-07 -0.040743380771" rpy="0 0 0"/>
      <geometry>
        <mesh filename="package://iCub/meshes/simmechanics/sim_sea_2-5_l_shoulder_2_prt-binary.stl" scale="0.001 0.001 0.001"/>
      </geometry>
    </collision>
  </link>
  <joint name="l_shoulder_roll" type="revolute">
    <origin xyz="-0.013671 0 0.0085204" rpy="0.270597317916 0.252680177542 -1.50155688559"/>
    <axis xyz="-0.258819 2.77555756156e-17 0.965926"/>
    <parent link="l_shoulder_1"/>
    <child link="l_shoulder_2"/>
    <limit effort="50000" lower="0.0" upper="2.80648943721" velocity="50000"/>
    <dynamics damping="0.06"/>
  </joint>
  <link name="l_shoulder_3">
    <inertial>
      <origin xyz="0.026798412222 -1.6e-05 0.0146956806177" rpy="0 0 0"/>
      <mass value="0.35913"/>
      <inertia ixx="0.01" ixy="0" ixz="0" iyy="0.01" iyz="0" izz="0.01"/>
    </inertial>
    <visual>
      <origin xyz="-0.131901037685 0 -0.0353427669194" rpy="0 0 0"/>
      <geometry>
        <mesh filename="package://iCub/meshes/simmechanics/sim_sea_2-5_l_upper_arm_prt-binary.stl" scale="0.001 0.001 0.001"/>
      </geometry>
      <material name="cyan"/>
    </visual>
    <collision>
      <origin xyz="-0.131901037685 0 -0.0353427669194" rpy="0 0 0"/>
      <geometry>
        <mesh filename="package://iCub/meshes/simmechanics/sim_sea_2-5_l_upper_arm_prt-binary.stl" scale="0.001 0.001 0.001"/>
      </geometry>
    </collision>
  </link>
  <joint name="l_shoulder_yaw" type="revolute">
    <origin xyz="0.0253143468312 1.11636438205e-07 -0.00540061656265" rpy="-0.252689546175 -0.0085186183214 -0.067039889142"/>
    <axis xyz="0.965925843882 2.22044604925e-16 0.258818979447"/>
    <parent link="l_shoulder_2"/>
    <child link="l_shoulder_3"/>
    <limit effort="50000" lower="-0.645771823238" upper="1.3962634016" velocity="50000"/>
    <dynamics damping="0.06"/>
  </joint>
  <link name="l_upper_arm">
    <inertial>
      <origin xyz="-0.006121 -0.000189 0.0293684" rpy="0 -1.30899700697 -3.14159265359"/>
      <mass value="0.746799"/>
      <inertia ixx="0.000509731" ixy="-6.90767e-07" ixz="1.20048e-05" iyy="0.00067086" iyz="3.11833e-06" izz="0.000601202"/>
    </inertial>
    <visual>
      <origin xyz="-0.015 0 -0.1933" rpy="0 -1.30899700697 -3.14159265359"/>
      <geometry>
        <mesh filename="package://iCub/meshes/simmechanics/sim_sea_2-5_l_elbow_prt-binary.stl" scale="0.001 0.001 0.001"/>
      </geometry>
      <material name="green"/>
    </visual>
    <collision>
      <origin xyz="-0.015 0 -0.1933" rpy="0 -1.30899700697 -3.14159265359"/>
      <geometry>
        <mesh filename="package://iCub/meshes/simmechanics/sim_sea_2-5_l_elbow_prt-binary.stl" scale="0.001 0.001 0.001"/>
      </geometry>
    </collision>
  </link>
  <joint name="l_arm_ft_sensor" type="fixed">
    <origin xyz="0.0509301432452 0 0.0291758294659" rpy="0 -1.30899700697 3.14159265359"/>
    <parent link="l_shoulder_3"/>
    <child link="l_upper_arm"/>
    <dynamics damping="0.1"/>
  </joint>
  <link name="l_elbow_1">
    <inertial>
      <origin xyz="0.00673912932843 0.0303019 -0.00465769236154" rpy="0 0 0"/>
      <mass value="0.267903"/>
      <inertia ixx="0.01" ixy="0" ixz="0" iyy="0.01" iyz="0" izz="0.01"/>
    </inertial>
    <visual>
      <origin xyz="-0.259390463317 0.0339999 -0.0850325886962" rpy="0 0 0"/>
      <geometry>
        <mesh filename="package://iCub/meshes/simmechanics/sim_sea_2-5_l_elbow_prosup_prt-binary.stl" scale="0.001 0.001 0.001"/>
      </geometry>
      <material name="white"/>
    </visual>
    <collision>
      <origin xyz="-0.259390463317 0.0339999 -0.0850325886962" rpy="0 0 0"/>
      <geometry>
        <mesh filename="package://iCub/meshes/simmechanics/sim_sea_2-5_l_elbow_prosup_prt-binary.stl" scale="0.001 0.001 0.001"/>
      </geometry>
    </collision>
  </link>
  <joint name="l_elbow" type="revolute">
    <origin xyz="0 0.0339999 0.07926" rpy="0 -1.30899700697 -3.14159265359"/>
    <axis xyz="2.22044604925e-16 -1.0 0.0"/>
    <parent link="l_upper_arm"/>
    <child link="l_elbow_1"/>
    <limit effort="50000" lower="0.261799387799" upper="1.85004900711" velocity="50000"/>
    <dynamics damping="0.06"/>
  </joint>
  <link name="l_forearm">
    <inertial>
      <origin xyz="0.0404511828823 -0.000686 0.00532363214379" rpy="0 0 0"/>
      <mass value="0.636185"/>
      <inertia ixx="0.000371447" ixy="4.34562e-06" ixz="-0.000105871" iyy="0.000674229" iyz="4.05222e-06" izz="0.000557115"/>
    </inertial>
    <visual>
      <origin xyz="-0.296886967375 0 -0.0795506015227" rpy="0 0 0"/>
      <geometry>
        <mesh filename="package://iCub/meshes/simmechanics/sim_sea_2-5_l_forearm_prt-binary.stl" scale="0.001 0.001 0.001"/>
      </geometry>
      <material name="dblue"/>
    </visual>
    <collision>
      <origin xyz="-0.296886967375 0 -0.0795506015227" rpy="0 0 0"/>
      <geometry>
        <mesh filename="package://iCub/meshes/simmechanics/sim_sea_2-5_l_forearm_prt-binary.stl" scale="0.001 0.001 0.001"/>
      </geometry>
    </collision>
  </link>
  <joint name="l_wrist_prosup" type="revolute">
    <origin xyz="0.0384624299027 0.0339999 -0.00522316819403" rpy="0 0 0"/>
    <axis xyz="0.965925843882 2.22044604925e-16 0.258818979447"/>
    <parent link="l_elbow_1"/>
    <child link="l_forearm"/>
    <limit effort="50000" lower="-1.0471975512" upper="1.0471975512" velocity="50000"/>
    <dynamics damping="0.06"/>
  </joint>
  <link name="l_forearm_skin_0"/>
  <joint name="l_forearm_skin_0_fixed_joint" type="fixed">
    <origin xyz="0.0454493286618 -0.0323169 -0.00628656037901" rpy="1.69181522292 -0.271026744341 0.0727882713185"/>
    <parent link="l_forearm"/>
    <child link="l_forearm_skin_0"/>
    <dynamics damping="0.1"/>
  </joint>
  <link name="l_forearm_skin_1"/>
  <joint name="l_forearm_skin_1_fixed_joint" type="fixed">
    <origin xyz="0.0333728935826 -0.0310662 -0.0198456867711" rpy="1.86694023278 -0.274442533764 0.0421228737473"/>
    <parent link="l_forearm"/>
    <child link="l_forearm_skin_1"/>
    <dynamics damping="0.1"/>
  </joint>
  <link name="l_forearm_skin_2"/>
  <joint name="l_forearm_skin_2_fixed_joint" type="fixed">
    <origin xyz="0.0146988929852 -0.0335184 -0.0160117338371" rpy="1.72847287019 -0.264015219116 0.0142600467197"/>
    <parent link="l_forearm"/>
    <child link="l_forearm_skin_2"/>
    <dynamics damping="0.1"/>
  </joint>
  <link name="l_forearm_skin_3"/>
  <joint name="l_forearm_skin_3_fixed_joint" type="fixed">
    <origin xyz="0.045567293622 0.028651 -0.00633000929351" rpy="-1.69487280859 -0.269757727104 -0.061995217851"/>
    <parent link="l_forearm"/>
    <child link="l_forearm_skin_3"/>
    <dynamics damping="0.1"/>
  </joint>
  <link name="l_forearm_skin_4"/>
  <joint name="l_forearm_skin_4_fixed_joint" type="fixed">
    <origin xyz="0.0635326332996 0.025877 -0.00899784258066" rpy="-1.81747870108 -0.287406884885 -0.0998316152826"/>
    <parent link="l_forearm"/>
    <child link="l_forearm_skin_4"/>
    <dynamics damping="0.1"/>
  </joint>
  <link name="l_forearm_skin_5"/>
  <joint name="l_forearm_skin_5_fixed_joint" type="fixed">
    <origin xyz="0.0688211941968 0.015709 -0.0231133361791" rpy="-2.5410475806 -0.385627260642 -0.0867227569203"/>
    <parent link="l_forearm"/>
    <child link="l_forearm_skin_5"/>
    <dynamics damping="0.1"/>
  </joint>
  <link name="l_forearm_skin_6"/>
  <joint name="l_forearm_skin_6_fixed_joint" type="fixed">
    <origin xyz="0.0333948436255 0.027308 -0.0198325583433" rpy="-1.86628164653 -0.272886336181 -0.0371068033783"/>
    <parent link="l_forearm"/>
    <child link="l_forearm_skin_6"/>
    <dynamics damping="0.1"/>
  </joint>
  <link name="l_forearm_skin_7"/>
  <joint name="l_forearm_skin_7_fixed_joint" type="fixed">
    <origin xyz="0.0147224260074 0.029702 -0.0159326482703" rpy="-1.72564640857 -0.263992900722 -0.0143801109253"/>
    <parent link="l_forearm"/>
    <child link="l_forearm_skin_7"/>
    <dynamics damping="0.1"/>
  </joint>
  <link name="l_forearm_skin_8"/>
  <joint name="l_forearm_skin_8_fixed_joint" type="fixed">
    <origin xyz="0.0228528628554 0.007546 -0.041885146375" rpy="-2.94801979137 -0.270605090512 -0.00178708074348"/>
    <parent link="l_forearm"/>
    <child link="l_forearm_skin_8"/>
    <dynamics damping="0.1"/>
  </joint>
  <link name="l_forearm_skin_9"/>
  <joint name="l_forearm_skin_9_fixed_joint" type="fixed">
    <origin xyz="0.0376032734683 0.016715 -0.0340163371186" rpy="-2.58406517708 -0.2933217196 -0.0203085796276"/>
    <parent link="l_forearm"/>
    <child link="l_forearm_skin_9"/>
    <dynamics damping="0.1"/>
  </joint>
  <link name="l_forearm_skin_10"/>
  <joint name="l_forearm_skin_10_fixed_joint" type="fixed">
    <origin xyz="0.0542285210888 0.007546 -0.0321469082866" rpy="-2.94123313406 -0.328304471922 -0.0139662781936"/>
    <parent link="l_forearm"/>
    <child link="l_forearm_skin_10"/>
    <dynamics damping="0.1"/>
  </joint>
  <link name="l_forearm_skin_11"/>
  <joint name="l_forearm_skin_11_fixed_joint" type="fixed">
    <origin xyz="0.0542240912024 -0.0112832 -0.0321431259452" rpy="2.93929835957 -0.329101389745 0.0142734891292"/>
    <parent link="l_forearm"/>
    <child link="l_forearm_skin_11"/>
    <dynamics damping="0.1"/>
  </joint>
  <link name="l_forearm_skin_12"/>
  <joint name="l_forearm_skin_12_fixed_joint" type="fixed">
    <origin xyz="0.0375994633868 -0.0204556 -0.0340191179961" rpy="2.58303505964 -0.29483050207 0.021326850448"/>
    <parent link="l_forearm"/>
    <child link="l_forearm_skin_12"/>
    <dynamics damping="0.1"/>
  </joint>
  <link name="l_forearm_skin_13"/>
  <joint name="l_forearm_skin_13_fixed_joint" type="fixed">
    <origin xyz="0.0228550868405 -0.0112878 -0.0418919009209" rpy="2.94896679198 -0.270583947189 0.00177385006765"/>
    <parent link="l_forearm"/>
    <child link="l_forearm_skin_13"/>
    <dynamics damping="0.1"/>
  </joint>
  <link name="l_forearm_skin_14"/>
  <joint name="l_forearm_skin_14_fixed_joint" type="fixed">
    <origin xyz="0.0687703276364 -0.0193999 -0.0230239558511" rpy="2.52462250363 -0.387794511771 0.0912924111683"/>
    <parent link="l_forearm"/>
    <child link="l_forearm_skin_14"/>
    <dynamics damping="0.1"/>
  </joint>
  <link name="l_forearm_skin_15"/>
  <joint name="l_forearm_skin_15_fixed_joint" type="fixed">
    <origin xyz="0.0633786419662 -0.0293843 -0.00879405455544" rpy="1.80492769741 -0.289783281916 0.113933739306"/>
    <parent link="l_forearm"/>
    <child link="l_forearm_skin_15"/>
    <dynamics damping="0.1"/>
  </joint>
  <link name="l_forearm_skin_16"/>
  <joint name="l_forearm_skin_16_fixed_joint" type="fixed">
    <origin xyz="0.03792482187 -0.0327268 0.0206369503605" rpy="1.41280007026 -0.25082462139 0.0758652301584"/>
    <parent link="l_forearm"/>
    <child link="l_forearm_skin_16"/>
    <dynamics damping="0.1"/>
  </joint>
  <link name="l_forearm_skin_17"/>
  <joint name="l_forearm_skin_17_fixed_joint" type="fixed">
    <origin xyz="0.0543170548821 -0.0299646 0.0303291240179" rpy="1.27223716205 -0.23059304703 0.109637225219"/>
    <parent link="l_forearm"/>
    <child link="l_forearm_skin_17"/>
    <dynamics damping="0.1"/>
  </joint>
  <link name="l_forearm_skin_19"/>
  <joint name="l_forearm_skin_19_fixed_joint" type="fixed">
    <origin xyz="0.0381266107138 0.029054 0.020690605393" rpy="-1.41560888703 -0.252569290226 -0.0644404747027"/>
    <parent link="l_forearm"/>
    <child link="l_forearm_skin_19"/>
    <dynamics damping="0.1"/>
  </joint>
  <link name="l_forearm_skin_22"/>
  <joint name="l_forearm_skin_22_fixed_joint" type="fixed">
    <origin xyz="0.0544173950421 0.026483 0.0306037516609" rpy="-1.2658242728 -0.234328151379 -0.0937094738802"/>
    <parent link="l_forearm"/>
    <child link="l_forearm_skin_22"/>
    <dynamics damping="0.1"/>
  </joint>
  <link name="l_forearm_skin_24"/>
  <joint name="l_forearm_skin_24_fixed_joint" type="fixed">
    <origin xyz="0.0700345319564 0.007477 0.050069108714" rpy="-0.23489327644 -0.0388172993982 -0.0548291989999"/>
    <parent link="l_forearm"/>
    <child link="l_forearm_skin_24"/>
    <dynamics damping="0.1"/>
  </joint>
  <link name="l_forearm_skin_25"/>
  <joint name="l_forearm_skin_25_fixed_joint" type="fixed">
    <origin xyz="0.0535999216295 0.015984 0.0454698125045" rpy="-0.564295527715 -0.136980272197 -0.0819608256656"/>
    <parent link="l_forearm"/>
    <child link="l_forearm_skin_25"/>
    <dynamics damping="0.1"/>
  </joint>
  <link name="l_forearm_skin_28"/>
  <joint name="l_forearm_skin_28_fixed_joint" type="fixed">
    <origin xyz="0.0535859272148 -0.0196522 0.045352037397" rpy="0.579311106949 -0.133994306778 0.0867597858312"/>
    <parent link="l_forearm"/>
    <child link="l_forearm_skin_28"/>
    <dynamics damping="0.1"/>
  </joint>
  <link name="l_forearm_skin_29"/>
  <joint name="l_forearm_skin_29_fixed_joint" type="fixed">
    <origin xyz="0.0700355805031 -0.0111936 0.0500111036233" rpy="0.248630982209 -0.0383136556786 0.0583026624266"/>
    <parent link="l_forearm"/>
    <child link="l_forearm_skin_29"/>
    <dynamics damping="0.1"/>
  </joint>
  <link name="l_forearm_dh_frame"/>
  <joint name="l_forearm_dh_frame_fixed_joint" type="fixed">
    <origin xyz="0.102871102373 7.00000000002e-06 0.0275642213111" rpy="2.87979333376 0 1.57079632679"/>
    <parent link="l_forearm"/>
    <child link="l_forearm_dh_frame"/>
    <dynamics damping="0.1"/>
  </joint>
  <link name="l_wrist_1">
    <inertial>
      <origin xyz="-0.000981313804428 -0.001178 0.00408345773913" rpy="0 0 0"/>
      <mass value="0.0362152"/>
      <inertia ixx="0.01" ixy="0" ixz="0" iyy="0.01" iyz="0" izz="0.01"/>
    </inertial>
    <visual>
      <origin xyz="-0.400314530555 -7.00000000009e-06 -0.105038082269" rpy="0 0 0"/>
      <geometry>
        <mesh filename="package://iCub/meshes/simmechanics/sim_sea_2-5_l_wrist_pitch_prt-binary.stl" scale="0.001 0.001 0.001"/>
      </geometry>
      <material name="dgreen"/>
    </visual>
    <collision>
      <origin xyz="-0.400314530555 -7.00000000009e-06 -0.105038082269" rpy="0 0 0"/>
      <geometry>
        <mesh filename="package://iCub/meshes/simmechanics/sim_sea_2-5_l_wrist_pitch_prt-binary.stl" scale="0.001 0.001 0.001"/>
      </geometry>
    </collision>
  </link>
  <joint name="l_wrist_pitch" type="revolute">
    <origin xyz="0.103427563179 7.00000000002e-06 0.0254874807467" rpy="0 0 0"/>
    <axis xyz="0.258818979447 0.0 -0.965925843882"/>
    <parent link="l_forearm"/>
    <child link="l_wrist_1"/>
    <limit effort="50000" lower="-1.3962634016" upper="0.436332312999" velocity="50000"/>
    <dynamics damping="0.06"/>
  </joint>
  <link name="l_hand">
    <inertial>
      <origin xyz="0.0647680204057 0.0056304 0.0226602208449" rpy="0 0 0"/>
      <mass value="0.247806"/>
      <inertia ixx="0.01" ixy="0" ixz="0" iyy="0.01" iyz="0" izz="0.01"/>
    </inertial>
    <visual>
      <origin xyz="-0.399680424055 0.0194929 -0.107404600587" rpy="0 0 0"/>
      <geometry>
        <mesh filename="package://iCub/meshes/simmechanics/sim_sea_2-5_l_hand_prt-binary.stl" scale="0.001 0.001 0.001"/>
      </geometry>
      <material name="gray"/>
    </visual>
    <collision>
      <origin xyz="-0.399680424055 0.0194929 -0.107404600587" rpy="0 0 0"/>
      <geometry>
        <mesh filename="package://iCub/meshes/simmechanics/sim_sea_2-5_l_hand_prt-binary.stl" scale="0.001 0.001 0.001"/>
      </geometry>
    </collision>
  </link>
  <joint name="l_wrist_yaw" type="revolute">
    <origin xyz="-0.000634106499644 -0.0194999 0.00236651831751" rpy="0 0 0"/>
    <axis xyz="-2.22044604925e-16 1.0 0.0"/>
    <parent link="l_wrist_1"/>
    <child link="l_hand"/>
    <limit effort="50000" lower="-0.349065850399" upper="0.436332312999" velocity="50000"/>
    <dynamics damping="0.06"/>
  </joint>
  <link name="l_hand_dh_frame"/>
  <joint name="l_hand_dh_frame_fixed_joint" type="fixed">
    <origin xyz="0.0576542978428 -0.0055568 0.0136938323083" rpy="-1.57079632679 -0.261799319827 0"/>
    <parent link="l_hand"/>
    <child link="l_hand_dh_frame"/>
    <dynamics damping="0.1"/>
  </joint>
  <link name="neck_1">
    <inertial>
      <origin xyz="0.0143705608 0.006567 -0.0063842" rpy="0 0 0"/>
      <mass value="0.125793"/>
      <inertia ixx="0.01" ixy="0" ixz="0" iyy="0.01" iyz="0" izz="0.01"/>
    </inertial>
    <visual>
      <origin xyz="0.0142999998093 -0.079997 -0.0295008" rpy="0 0 0"/>
      <geometry>
        <mesh filename="package://iCub/meshes/simmechanics/sim_sea_2-5_neck_1_prt-binary.stl" scale="0.001 0.001 0.001"/>
      </geometry>
      <material name="green"/>
    </visual>
    <collision>
      <origin xyz="0.0142999998093 -0.079997 -0.0295008" rpy="0 0 0"/>
      <geometry>
        <mesh filename="package://iCub/meshes/simmechanics/sim_sea_2-5_neck_1_prt-binary.stl" scale="0.001 0.001 0.001"/>
      </geometry>
    </collision>
  </link>
  <joint name="neck_pitch" type="revolute">
    <origin xyz="-0.0142999998093 0.172797 0.0053118" rpy="0 0 0"/>
    <axis xyz="-1.0 0.0 0.0"/>
    <parent link="chest"/>
    <child link="neck_1"/>
    <limit effort="50000" lower="-0.698131700798" upper="0.383972435439" velocity="50000"/>
    <dynamics damping="0.06"/>
  </joint>
  <link name="neck_2">
    <inertial>
      <origin xyz="-8.8573009265e-05 0.035225 -0.01954527" rpy="0 0 0"/>
      <mass value="0.177087"/>
      <inertia ixx="0.01" ixy="0" ixz="0" iyy="0.01" iyz="0" izz="0.01"/>
    </inertial>
    <visual>
      <origin xyz="0 -0.089497 -0.05030077" rpy="0 0 0"/>
      <geometry>
        <mesh filename="package://iCub/meshes/simmechanics/sim_sea_2-5_neck_2_prt-binary.stl" scale="0.001 0.001 0.001"/>
      </geometry>
      <material name="black"/>
    </visual>
    <collision>
      <origin xyz="0 -0.089497 -0.05030077" rpy="0 0 0"/>
      <geometry>
        <mesh filename="package://iCub/meshes/simmechanics/sim_sea_2-5_neck_2_prt-binary.stl" scale="0.001 0.001 0.001"/>
      </geometry>
    </collision>
  </link>
  <joint name="neck_roll" type="revolute">
    <origin xyz="0.0142999998093 0.0095 0.02079997" rpy="0 0 0"/>
    <axis xyz="0.0 0.0 1.0"/>
    <parent link="neck_1"/>
    <child link="neck_2"/>
    <limit effort="50000" lower="-0.349065850399" upper="0.349065850399" velocity="50000"/>
    <dynamics damping="0.06"/>
  </joint>
  <link name="head">
    <inertial>
      <origin xyz="-0.000574157809265 0.113511 -0.0075392" rpy="0 0 0"/>
      <mass value="1.50691"/>
      <inertia ixx="0.00680478" ixy="-1.60267e-05" ixz="7.28166e-05" iyy="0.00634736" iyz="0.000292091" izz="0.00478116"/>
    </inertial>
    <visual>
      <origin xyz="0 -0.067153 -0.0295008" rpy="0 0 0"/>
      <geometry>
        <mesh filename="package://iCub/meshes/simmechanics/sim_sea_2-5_head_prt-binary.stl" scale="0.001 0.001 0.001"/>
      </geometry>
      <material name="red"/>
    </visual>
    <collision>
      <origin xyz="0 -0.067153 -0.0295008" rpy="0 0 0"/>
      <geometry>
        <mesh filename="package://iCub/meshes/simmechanics/sim_sea_2-5_head_prt-binary.stl" scale="0.001 0.001 0.001"/>
      </geometry>
    </collision>
  </link>
  <joint name="neck_yaw" type="revolute">
    <origin xyz="0 -0.022344 -0.02079997" rpy="0 0 0"/>
    <axis xyz="0.0 1.0 0.0"/>
    <parent link="neck_2"/>
    <child link="head"/>
    <limit effort="50000" lower="-0.872664625997" upper="0.872664625997" velocity="50000"/>
    <dynamics damping="0.06"/>
  </joint>
  <link name="imu_frame"/>
  <joint name="imu_frame_fixed_joint" type="fixed">
    <origin xyz="0.00950000019074 0.133444 0.0093" rpy="-1.57079632679 1.57079632679 0"/>
    <parent link="head"/>
    <child link="imu_frame"/>
    <dynamics damping="0.1"/>
  </joint>
  <gazebo reference="l_leg_ft_sensor">
    <sensor name="l_leg_ft_sensor" type="force_torque">
      <always_on>1</always_on>
      <update_rate>100</update_rate>
      <force_torque>
        <frame>child</frame>
        <measure_direction>child_to_parent</measure_direction>
      </force_torque>
    </sensor>
  </gazebo>
  <sensor name="l_leg_ft_sensor" type="force_torque">
    <parent joint="l_leg_ft_sensor"/>
    <force_torque>
      <frame>child</frame>
      <measure_direction>child_to_parent</measure_direction>
    </force_torque>
  </sensor>
  <gazebo reference="r_leg_ft_sensor">
    <sensor name="r_leg_ft_sensor" type="force_torque">
      <always_on>1</always_on>
      <update_rate>100</update_rate>
      <force_torque>
        <frame>child</frame>
        <measure_direction>child_to_parent</measure_direction>
      </force_torque>
    </sensor>
  </gazebo>
  <sensor name="r_leg_ft_sensor" type="force_torque">
    <parent joint="r_leg_ft_sensor"/>
    <force_torque>
      <frame>child</frame>
      <measure_direction>child_to_parent</measure_direction>
    </force_torque>
  </sensor>
  <gazebo reference="l_foot_ft_sensor">
    <sensor name="l_foot_ft_sensor" type="force_torque">
      <always_on>1</always_on>
      <update_rate>100</update_rate>
      <force_torque>
        <frame>child</frame>
        <measure_direction>child_to_parent</measure_direction>
      </force_torque>
    </sensor>
  </gazebo>
  <sensor name="l_foot_ft_sensor" type="force_torque">
    <parent joint="l_foot_ft_sensor"/>
    <force_torque>
      <frame>child</frame>
      <measure_direction>child_to_parent</measure_direction>
    </force_torque>
  </sensor>
  <gazebo reference="r_foot_ft_sensor">
    <sensor name="r_foot_ft_sensor" type="force_torque">
      <always_on>1</always_on>
      <update_rate>100</update_rate>
      <force_torque>
        <frame>child</frame>
        <measure_direction>child_to_parent</measure_direction>
      </force_torque>
    </sensor>
  </gazebo>
  <sensor name="r_foot_ft_sensor" type="force_torque">
    <parent joint="r_foot_ft_sensor"/>
    <force_torque>
      <frame>child</frame>
      <measure_direction>child_to_parent</measure_direction>
    </force_torque>
  </sensor>
  <gazebo reference="l_arm_ft_sensor">
    <sensor name="l_arm_ft_sensor" type="force_torque">
      <always_on>1</always_on>
      <update_rate>100</update_rate>
      <force_torque>
        <frame>child</frame>
        <measure_direction>child_to_parent</measure_direction>
      </force_torque>
    </sensor>
  </gazebo>
  <sensor name="l_arm_ft_sensor" type="force_torque">
    <parent joint="l_arm_ft_sensor"/>
    <force_torque>
      <frame>child</frame>
      <measure_direction>child_to_parent</measure_direction>
    </force_torque>
  </sensor>
  <gazebo reference="r_arm_ft_sensor">
    <sensor name="r_arm_ft_sensor" type="force_torque">
      <always_on>1</always_on>
      <update_rate>100</update_rate>
      <force_torque>
        <frame>child</frame>
        <measure_direction>child_to_parent</measure_direction>
      </force_torque>
    </sensor>
  </gazebo>
  <sensor name="r_arm_ft_sensor" type="force_torque">
    <parent joint="r_arm_ft_sensor"/>
    <force_torque>
      <frame>child</frame>
      <measure_direction>child_to_parent</measure_direction>
    </force_torque>
  </sensor>
  <gazebo reference="head">
    <sensor name="head_imu_acc_1x1" type="imu">
      <always_on>1</always_on>
      <update_rate>100</update_rate>
      <pose>0.00950000019074 0.133444 0.0093 -1.57079632679 1.57079632679 0.0</pose>
      <plugin name="iCub_yarp_gazebo_plugin_IMU" filename="libgazebo_yarp_imu.so">
    <yarpConfigurationFile>model://iCub/conf/gazebo_icub_inertial.ini</yarpConfigurationFile>
</plugin>
    </sensor>
  </gazebo>
  <sensor name="head_imu_acc_1x1" type="accelerometer">
    <parent link="head"/>
    <origin rpy="-1.57079632679 1.57079632679 0.0" xyz="0.00950000019074 0.133444 0.0093"/>
  </sensor>
  <link name="base_link"/>
  <joint name="base_fixed_joint" type="fixed">
  <origin xyz="0 0 0" rpy="0 -0 0"/>
  <axis xyz="0 0 0"/>
  <parent link="base_link"/>
  <child link="root_link"/>
</joint>
  <link name="l_foot_dh_frame"/>
  <joint name="l_foot_dh_frame_fixed_joint" type="fixed">
  <origin xyz="0.0 0 0.004" rpy="0 1.5708 0"/>
  <axis xyz="0 0 0"/>
  <parent link="l_foot"/>
  <child link="l_foot_dh_frame"/>
</joint>
  <link name="r_foot_dh_frame"/>
  <joint name="r_foot_dh_frame_fixed_joint" type="fixed">
  <origin xyz="0.0 0 0.004" rpy="0 1.5708 0"/>
  <axis xyz="0 0 0"/>
  <parent link="r_foot"/>
  <child link="r_foot_dh_frame"/>
</joint>
<gazebo reference="l_foot">
  <collision> <surface> <bounce>
    <restitution_coefficient>0</restitution_coefficient>
    <threshold>100000</threshold>
  </bounce> </surface> </collision>
  <maxContacts>4</maxContacts>
  <kp>18000000</kp>
  <kd>100</kd>
  <maxVel>100</maxVel>
  <minDepth>0.0001</minDepth>
  <mu1>1</mu1>
  <mu2>1</mu2>
  <fdir1>0 0 0</fdir1>
</gazebo>
<gazebo reference="r_foot">
  <collision> <surface> <bounce>
    <restitution_coefficient>0</restitution_coefficient>
    <threshold>100000</threshold>
  </bounce> </surface> </collision>
  <maxContacts>4</maxContacts>
  <kp>18000000</kp>
  <kd>100</kd>
  <maxVel>100</maxVel>
  <minDepth>0.0001</minDepth>
  <mu1>1</mu1>
  <mu2>1</mu2>
  <fdir1>0 0 0</fdir1>
</gazebo>
  <gazebo reference="r_arm_ft_sensor">
  <disableFixedJointLumping>true</disableFixedJointLumping>
</gazebo>
  <gazebo reference="l_arm_ft_sensor">
  <disableFixedJointLumping>true</disableFixedJointLumping>
</gazebo>
  <gazebo reference="r_leg_ft_sensor">
  <disableFixedJointLumping>true</disableFixedJointLumping>
</gazebo>
  <gazebo reference="l_leg_ft_sensor">
  <disableFixedJointLumping>true</disableFixedJointLumping>
</gazebo>
  <gazebo reference="r_foot_ft_sensor">
  <disableFixedJointLumping>true</disableFixedJointLumping>
</gazebo>
  <gazebo reference="l_foot_ft_sensor">
  <disableFixedJointLumping>true</disableFixedJointLumping>
</gazebo>
  <gazebo reference="torso_pitch">
  <implicitSpringDamper>1</implicitSpringDamper>
</gazebo>
  <gazebo reference="torso_roll">
  <implicitSpringDamper>1</implicitSpringDamper>
</gazebo>
  <gazebo reference="torso_yaw">
  <implicitSpringDamper>1</implicitSpringDamper>
</gazebo>
  <gazebo reference="l_shoulder_pitch">
  <implicitSpringDamper>1</implicitSpringDamper>
</gazebo>
  <gazebo reference="l_shoulder_roll">
  <implicitSpringDamper>1</implicitSpringDamper>
</gazebo>
  <gazebo reference="l_shoulder_yaw">
  <implicitSpringDamper>1</implicitSpringDamper>
</gazebo>
  <gazebo reference="l_arm_ft_sensor">
  <implicitSpringDamper>1</implicitSpringDamper>
</gazebo>
  <gazebo reference="l_elbow">
  <implicitSpringDamper>1</implicitSpringDamper>
</gazebo>
  <gazebo reference="l_wrist_prosup">
  <implicitSpringDamper>1</implicitSpringDamper>
</gazebo>
  <gazebo reference="l_wrist_pitch">
  <implicitSpringDamper>1</implicitSpringDamper>
</gazebo>
  <gazebo reference="l_wrist_yaw">
  <implicitSpringDamper>1</implicitSpringDamper>
</gazebo>
  <gazebo reference="r_shoulder_pitch">
  <implicitSpringDamper>1</implicitSpringDamper>
</gazebo>
  <gazebo reference="r_shoulder_roll">
  <implicitSpringDamper>1</implicitSpringDamper>
</gazebo>
  <gazebo reference="r_shoulder_yaw">
  <implicitSpringDamper>1</implicitSpringDamper>
</gazebo>
  <gazebo reference="r_arm_ft_sensor">
  <implicitSpringDamper>1</implicitSpringDamper>
</gazebo>
  <gazebo reference="r_elbow">
  <implicitSpringDamper>1</implicitSpringDamper>
</gazebo>
  <gazebo reference="r_wrist_prosup">
  <implicitSpringDamper>1</implicitSpringDamper>
</gazebo>
  <gazebo reference="r_wrist_pitch">
  <implicitSpringDamper>1</implicitSpringDamper>
</gazebo>
  <gazebo reference="l_wrist_yaw">
  <implicitSpringDamper>1</implicitSpringDamper>
</gazebo>
  <gazebo reference="l_hip_pitch">
  <implicitSpringDamper>1</implicitSpringDamper>
</gazebo>
  <gazebo reference="l_hip_roll">
  <implicitSpringDamper>1</implicitSpringDamper>
</gazebo>
  <gazebo reference="l_hip_yaw">
  <implicitSpringDamper>1</implicitSpringDamper>
</gazebo>
  <gazebo reference="l_knee">
  <implicitSpringDamper>1</implicitSpringDamper>
</gazebo>
  <gazebo reference="l_ankle_pitch">
  <implicitSpringDamper>1</implicitSpringDamper>
</gazebo>
  <gazebo reference="l_ankle_roll">
  <implicitSpringDamper>1</implicitSpringDamper>
</gazebo>
  <gazebo reference="r_hip_pitch">
  <implicitSpringDamper>1</implicitSpringDamper>
</gazebo>
  <gazebo reference="r_hip_roll">
  <implicitSpringDamper>1</implicitSpringDamper>
</gazebo>
  <gazebo reference="r_hip_yaw">
  <implicitSpringDamper>1</implicitSpringDamper>
</gazebo>
  <gazebo reference="r_knee">
  <implicitSpringDamper>1</implicitSpringDamper>
</gazebo>
  <gazebo reference="r_ankle_pitch">
  <implicitSpringDamper>1</implicitSpringDamper>
</gazebo>
  <gazebo reference="r_ankle_roll">
  <implicitSpringDamper>1</implicitSpringDamper>
</gazebo>
  <gazebo>
<plugin name="controlboard_torso" filename="libgazebo_yarp_controlboard.so">
    <yarpConfigurationFile>model://iCub/conf/gazebo_icub_torso.ini</yarpConfigurationFile>
</plugin>
<plugin name="controlboard_head_without_eyes" filename="libgazebo_yarp_controlboard.so">
    <yarpConfigurationFile>model://iCub/conf/gazebo_icub_head_without_eyes.ini</yarpConfigurationFile>
</plugin>
<plugin name="controlboard_left_arm_no_hand" filename="libgazebo_yarp_controlboard.so">
    <yarpConfigurationFile>model://iCub/conf/gazebo_icub_left_arm_no_hand_for_no_hand_model.ini</yarpConfigurationFile>
    <initialConfiguration>-0.52 0.52 0 0.785 0 0 0.698</initialConfiguration>
</plugin>
<plugin name="controlboard_right_arm_no_hand" filename="libgazebo_yarp_controlboard.so">
    <yarpConfigurationFile>model://iCub/conf/gazebo_icub_right_arm_no_hand_for_no_hand_model.ini</yarpConfigurationFile>
    <initialConfiguration>-0.52 0.52 0 0.785 0 0 0.698</initialConfiguration>
</plugin>
<plugin name="controlboard_right_leg" filename="libgazebo_yarp_controlboard.so">
    <yarpConfigurationFile>model://iCub/conf/gazebo_icub_right_leg.ini</yarpConfigurationFile>
</plugin>
<plugin name="controlboard_left_leg" filename="libgazebo_yarp_controlboard.so">
    <yarpConfigurationFile>model://iCub/conf/gazebo_icub_left_leg.ini</yarpConfigurationFile>
</plugin>
<plugin name="apply_external_wrench" filename="libgazebo_yarp_externalwrench.so">
     <robotNamefromConfigFile>model://iCub/conf/gazebo_icub_robotname.ini</robotNamefromConfigFile>
</plugin>
</gazebo>
</robot>
